[2025-07-28 12:51:31,788] INFO django.request - [angel] Validaciones fallidas para 'Base de Datos BIA.xlsx': ["La columna 'dni' es obligatoria y no está presente."]
[2025-07-28 12:51:31,948] WARNING django.request - Bad Request: /carga-datos/api/
[2025-07-28 13:10:57,810] ERROR django.request - [angel] Error inesperado en API al procesar 'Base de Datos BIA.xlsx': column db_bia.DNI does not exist
LINE 1: SELECT "db_bia"."DNI" FROM "db_bia"
               ^
Traceback (most recent call last):
  File "/Users/angel/Desktop/Proyecto Grupo BIA/GrupoBIA/venvGrupoBIA/lib/python3.12/site-packages/django/db/backends/utils.py", line 105, in _execute
    return self.cursor.execute(sql, params)
           ^^^^^^^^^^^^^^^^^^^^^^^^^^^^^^^^
psycopg2.errors.UndefinedColumn: column db_bia.DNI does not exist
LINE 1: SELECT "db_bia"."DNI" FROM "db_bia"
               ^


The above exception was the direct cause of the following exception:

Traceback (most recent call last):
  File "/Users/angel/Desktop/Proyecto Grupo BIA/GrupoBIA/proyecto_bia/proyecto_bia/carga_datos/views.py", line 158, in api_cargar_excel
    dnis_existentes = set(BaseDeDatosBia.objects.values_list('dni', flat=True))
                      ^^^^^^^^^^^^^^^^^^^^^^^^^^^^^^^^^^^^^^^^^^^^^^^^^^^^^^^^^
  File "/Users/angel/Desktop/Proyecto Grupo BIA/GrupoBIA/venvGrupoBIA/lib/python3.12/site-packages/django/db/models/query.py", line 400, in __iter__
    self._fetch_all()
  File "/Users/angel/Desktop/Proyecto Grupo BIA/GrupoBIA/venvGrupoBIA/lib/python3.12/site-packages/django/db/models/query.py", line 1928, in _fetch_all
    self._result_cache = list(self._iterable_class(self))
                         ^^^^^^^^^^^^^^^^^^^^^^^^^^^^^^^^
  File "/Users/angel/Desktop/Proyecto Grupo BIA/GrupoBIA/venvGrupoBIA/lib/python3.12/site-packages/django/db/models/query.py", line 287, in __iter__
    for row in compiler.results_iter(
               ^^^^^^^^^^^^^^^^^^^^^^
  File "/Users/angel/Desktop/Proyecto Grupo BIA/GrupoBIA/venvGrupoBIA/lib/python3.12/site-packages/django/db/models/sql/compiler.py", line 1525, in results_iter
    results = self.execute_sql(
              ^^^^^^^^^^^^^^^^^
  File "/Users/angel/Desktop/Proyecto Grupo BIA/GrupoBIA/venvGrupoBIA/lib/python3.12/site-packages/django/db/models/sql/compiler.py", line 1574, in execute_sql
    cursor.execute(sql, params)
  File "/Users/angel/Desktop/Proyecto Grupo BIA/GrupoBIA/venvGrupoBIA/lib/python3.12/site-packages/django/db/backends/utils.py", line 122, in execute
    return super().execute(sql, params)
           ^^^^^^^^^^^^^^^^^^^^^^^^^^^^
  File "/Users/angel/Desktop/Proyecto Grupo BIA/GrupoBIA/venvGrupoBIA/lib/python3.12/site-packages/django/db/backends/utils.py", line 79, in execute
    return self._execute_with_wrappers(
           ^^^^^^^^^^^^^^^^^^^^^^^^^^^^
  File "/Users/angel/Desktop/Proyecto Grupo BIA/GrupoBIA/venvGrupoBIA/lib/python3.12/site-packages/django/db/backends/utils.py", line 92, in _execute_with_wrappers
    return executor(sql, params, many, context)
           ^^^^^^^^^^^^^^^^^^^^^^^^^^^^^^^^^^^^
  File "/Users/angel/Desktop/Proyecto Grupo BIA/GrupoBIA/venvGrupoBIA/lib/python3.12/site-packages/django/db/backends/utils.py", line 100, in _execute
    with self.db.wrap_database_errors:
         ^^^^^^^^^^^^^^^^^^^^^^^^^^^^
  File "/Users/angel/Desktop/Proyecto Grupo BIA/GrupoBIA/venvGrupoBIA/lib/python3.12/site-packages/django/db/utils.py", line 91, in __exit__
    raise dj_exc_value.with_traceback(traceback) from exc_value
  File "/Users/angel/Desktop/Proyecto Grupo BIA/GrupoBIA/venvGrupoBIA/lib/python3.12/site-packages/django/db/backends/utils.py", line 105, in _execute
    return self.cursor.execute(sql, params)
           ^^^^^^^^^^^^^^^^^^^^^^^^^^^^^^^^
django.db.utils.ProgrammingError: column db_bia.DNI does not exist
LINE 1: SELECT "db_bia"."DNI" FROM "db_bia"
               ^

[2025-07-28 13:10:57,814] ERROR django.request - Internal Server Error: /carga-datos/api/
[2025-07-28 13:12:05,393] WARNING django.request - Unauthorized: /carga-datos/api/
[2025-07-28 13:12:26,519] INFO django.request - [angel] Validaciones fallidas para 'Base de Datos BIA.xlsx': ["La columna 'dni' es obligatoria y no está presente."]
[2025-07-28 13:12:26,674] WARNING django.request - Bad Request: /carga-datos/api/
[2025-07-28 13:28:07,468] ERROR django.request - [angel] Error inesperado en carga: The `request` argument must be an instance of `django.http.HttpRequest`, not `pandas.core.indexes.base.Index`.
Traceback (most recent call last):
  File "/Users/angel/Desktop/Proyecto Grupo BIA/GrupoBIA/proyecto_bia/proyecto_bia/carga_datos/views.py", line 195, in api_cargar_excel
    faltantes = validar_columnas_obligatorias(df.columns)
                ^^^^^^^^^^^^^^^^^^^^^^^^^^^^^^^^^^^^^^^^^
  File "/Users/angel/Desktop/Proyecto Grupo BIA/GrupoBIA/venvGrupoBIA/lib/python3.12/site-packages/django/views/decorators/csrf.py", line 65, in _view_wrapper
    return view_func(request, *args, **kwargs)
           ^^^^^^^^^^^^^^^^^^^^^^^^^^^^^^^^^^^
  File "/Users/angel/Desktop/Proyecto Grupo BIA/GrupoBIA/venvGrupoBIA/lib/python3.12/site-packages/django/views/generic/base.py", line 104, in view
    return self.dispatch(request, *args, **kwargs)
           ^^^^^^^^^^^^^^^^^^^^^^^^^^^^^^^^^^^^^^^
  File "/Users/angel/Desktop/Proyecto Grupo BIA/GrupoBIA/venvGrupoBIA/lib/python3.12/site-packages/rest_framework/views.py", line 498, in dispatch
    request = self.initialize_request(request, *args, **kwargs)
              ^^^^^^^^^^^^^^^^^^^^^^^^^^^^^^^^^^^^^^^^^^^^^^^^^
  File "/Users/angel/Desktop/Proyecto Grupo BIA/GrupoBIA/venvGrupoBIA/lib/python3.12/site-packages/rest_framework/views.py", line 397, in initialize_request
    return Request(
           ^^^^^^^^
  File "/Users/angel/Desktop/Proyecto Grupo BIA/GrupoBIA/venvGrupoBIA/lib/python3.12/site-packages/rest_framework/request.py", line 154, in __init__
    assert isinstance(request, HttpRequest), (
           ^^^^^^^^^^^^^^^^^^^^^^^^^^^^^^^^
AssertionError: The `request` argument must be an instance of `django.http.HttpRequest`, not `pandas.core.indexes.base.Index`.
[2025-07-28 13:28:07,470] ERROR django.request - Internal Server Error: /carga-datos/api/
[2025-07-28 23:38:04,384] INFO django.request - [angel] Faltan columnas en archivo 'Base de Datos BIA.xlsx': ['id_pago_unico', 'entidad_original_1', 'entidad_original_2', 'nombre_apellido', 'fecha_apertura', 'fecha_deuda', 'saldo_capital', 'saldo_exigible', 'interes_diario', 'interes_total', 'saldo_actualizado', 'cancel_min', 'cod_rp', 'sub_estado', 'tel_1', 'tel_2', 'tel_3', 'tel_4', 'tel_5', 'mail_1', 'mail_2', 'mail_3', 'pago_acumulado', 'ultima_fecha_pago', 'fecha_plan', 'total_plan']
[2025-07-28 23:38:04,384] WARNING django.request - Bad Request: /carga-datos/api/
[2025-07-28 23:50:50,215] INFO django.request - [angel] Faltan columnas en archivo 'Base de Datos BIA.xlsx': ['id_pago_unico', 'entidad_original_1', 'entidad_original_2', 'nombre_apellido', 'fecha_apertura', 'fecha_deuda', 'saldo_capital', 'saldo_exigible', 'interes_diario', 'interes_total', 'saldo_actualizado', 'cancel_min', 'cod_rp', 'sub_estado', 'tel_1', 'tel_2', 'tel_3', 'tel_4', 'tel_5', 'mail_1', 'mail_2', 'mail_3', 'pago_acumulado', 'ultima_fecha_pago', 'fecha_plan', 'total_plan']
[2025-07-28 23:50:50,215] WARNING django.request - Bad Request: /carga-datos/api/
[2025-07-29 00:00:19,098] INFO django.request - [angel] Faltan columnas en archivo 'Base de Datos BIA.xlsx': ['id_pago_unico', 'entidad_original_1', 'entidad_original_2', 'nombre_apellido', 'fecha_apertura', 'fecha_deuda', 'saldo_capital', 'saldo_exigible', 'interes_diario', 'interes_total', 'saldo_actualizado', 'cancel_min', 'cod_rp', 'sub_estado', 'tel_1', 'tel_2', 'tel_3', 'tel_4', 'tel_5', 'mail_1', 'mail_2', 'mail_3', 'pago_acumulado', 'ultima_fecha_pago', 'fecha_plan', 'total_plan']
[2025-07-29 00:00:19,105] WARNING django.request - Bad Request: /carga-datos/api/
[2025-07-29 00:01:11,665] INFO django.request - [angel] Faltan columnas en archivo 'Base de Datos BIA.xlsx': ['id_pago_unico', 'entidad_original_1', 'entidad_original_2', 'nombre_apellido', 'fecha_apertura', 'fecha_deuda', 'saldo_capital', 'saldo_exigible', 'interes_diario', 'interes_total', 'saldo_actualizado', 'cancel_min', 'cod_rp', 'sub_estado', 'tel_1', 'tel_2', 'tel_3', 'tel_4', 'tel_5', 'mail_1', 'mail_2', 'mail_3', 'pago_acumulado', 'ultima_fecha_pago', 'fecha_plan', 'total_plan']
[2025-07-29 00:01:11,665] WARNING django.request - Bad Request: /carga-datos/api/
[2025-07-29 00:09:23,796] INFO django.request - [angel] Faltan columnas en archivo 'Base de Datos BIA.xlsx': ['id_pago_unico', 'entidad_original_1', 'entidad_original_2', 'nombre_apellido', 'fecha_apertura', 'fecha_deuda', 'saldo_capital', 'saldo_exigible', 'interes_diario', 'interes_total', 'saldo_actualizado', 'cancel_min', 'cod_rp', 'sub_estado', 'tel_1', 'tel_2', 'tel_3', 'tel_4', 'tel_5', 'mail_1', 'mail_2', 'mail_3', 'pago_acumulado', 'ultima_fecha_pago', 'fecha_plan', 'total_plan']
[2025-07-29 00:09:23,796] WARNING django.request - Bad Request: /carga-datos/api/
[2025-07-29 00:12:22,978] INFO django.request - [angel] Faltan columnas en archivo 'Base de Datos BIA.xlsx': ['id_pago_unico', 'entidad_original_1', 'entidad_original_2', 'nombre_apellido', 'fecha_apertura', 'fecha_deuda', 'saldo_capital', 'saldo_exigible', 'interes_diario', 'interes_total', 'saldo_actualizado', 'cancel_min', 'cod_rp', 'sub_estado', 'tel_1', 'tel_2', 'tel_3', 'tel_4', 'tel_5', 'mail_1', 'mail_2', 'mail_3', 'pago_acumulado', 'ultima_fecha_pago', 'fecha_plan', 'total_plan']
[2025-07-29 00:12:22,978] WARNING django.request - Bad Request: /carga-datos/api/
[2025-07-29 00:15:28,640] INFO django.request - [angel] Faltan columnas en archivo 'Base de Datos BIA.xlsx': ['id_pago_unico', 'entidad_original_1', 'entidad_original_2', 'nombre_apellido', 'fecha_apertura', 'fecha_deuda', 'saldo_capital', 'saldo_exigible', 'interes_diario', 'interes_total', 'saldo_actualizado', 'cancel_min', 'cod_rp', 'sub_estado', 'tel_1', 'tel_2', 'tel_3', 'tel_4', 'tel_5', 'mail_1', 'mail_2', 'mail_3', 'pago_acumulado', 'ultima_fecha_pago', 'fecha_plan', 'total_plan']
[2025-07-29 00:15:28,640] WARNING django.request - Bad Request: /carga-datos/api/
[2025-07-29 00:18:25,085] INFO django.request - [angel] Faltan columnas en archivo 'Base de Datos BIA.xlsx': ['entidad_original_2', 'nombre_apellido', 'fecha_apertura', 'ultima_fecha_pago']
[2025-07-29 00:18:25,086] WARNING django.request - Bad Request: /carga-datos/api/
[2025-07-29 00:43:42,620] INFO django.request - [angel] Faltan columnas en archivo 'Base de Datos BIA.xlsx': ['entidad_original_2', 'nombre_apellido', 'fecha_apertura', 'ultima_fecha_pago']
[2025-07-29 00:43:42,620] WARNING django.request - Bad Request: /carga-datos/api/
[2025-07-29 00:44:35,635] INFO django.request - [angel] Faltan columnas en archivo 'Base de Datos BIA.xlsx': ['entidad_original_2', 'nombre_apellido', 'fecha_apertura', 'ultima_fecha_pago']
[2025-07-29 00:44:35,636] WARNING django.request - Bad Request: /carga-datos/api/
[2025-07-29 01:02:31,449] INFO django.request - [angel] Faltan columnas en archivo 'Base de Datos BIA.xlsx': ['entidad_original_2', 'nombre_apellido', 'fecha_apertura', 'ultima_fecha_pago']
[2025-07-29 01:02:31,450] WARNING django.request - Bad Request: /carga-datos/api/
[2025-07-29 01:17:05,467] INFO django.request - [angel] Previsualización cargada de 'Base de Datos BIA.xlsx' con 14 registros.
[2025-07-29 01:17:50,604] WARNING django.request - [angel] Intentó confirmar carga sin datos en sesión.
[2025-07-29 01:17:50,607] WARNING django.request - Bad Request: /carga-datos/api/confirmar/
[2025-07-29 01:17:50,619] WARNING django.request - [angel] Intentó confirmar carga sin datos en sesión.
[2025-07-29 01:17:50,620] WARNING django.request - Bad Request: /carga-datos/api/confirmar/
[2025-07-29 01:20:46,996] INFO django.request - [angel] Previsualización cargada de 'Base de Datos BIA.xlsx' con 14 registros.
[2025-07-29 01:20:49,311] WARNING django.request - [angel] Intentó confirmar carga sin datos en sesión.
[2025-07-29 01:20:49,312] WARNING django.request - Bad Request: /carga-datos/api/confirmar/
[2025-07-29 01:20:49,323] WARNING django.request - [angel] Intentó confirmar carga sin datos en sesión.
[2025-07-29 01:20:49,323] WARNING django.request - Bad Request: /carga-datos/api/confirmar/
[2025-07-29 01:30:13,433] WARNING django.request - Bad Request: /carga-datos/api/confirmar/
[2025-07-29 01:30:13,448] WARNING django.request - Bad Request: /carga-datos/api/confirmar/
[2025-07-29 01:30:22,459] WARNING django.request - Unauthorized: /api/token/
[2025-07-29 01:30:39,119] INFO django.request - [angel] Previsualización cargada de 'Base de Datos BIA.xlsx' con 14 registros.
[2025-07-29 01:30:42,025] WARNING django.request - Bad Request: /carga-datos/api/confirmar/
[2025-07-29 01:30:42,027] WARNING django.request - Bad Request: /carga-datos/api/confirmar/
[2025-07-29 01:39:12,871] WARNING django.request - Bad Request: /carga-datos/api/confirmar/
[2025-07-29 01:39:12,872] WARNING django.request - Bad Request: /carga-datos/api/confirmar/
[2025-07-29 01:39:32,700] WARNING django.request - Bad Request: /carga-datos/api/confirmar/
[2025-07-29 01:39:32,702] WARNING django.request - Bad Request: /carga-datos/api/confirmar/
[2025-07-29 01:40:05,812] WARNING django.request - Bad Request: /carga-datos/api/confirmar/
[2025-07-29 01:40:05,849] WARNING django.request - Bad Request: /carga-datos/api/confirmar/
[2025-07-29 01:47:39,364] WARNING django.request - Unauthorized: /carga-datos/api/confirmar/
[2025-07-29 01:47:39,910] WARNING django.request - Bad Request: /carga-datos/api/confirmar/
[2025-07-29 01:47:58,546] WARNING django.request - Bad Request: /carga-datos/api/confirmar/
[2025-07-29 01:47:58,551] WARNING django.request - Bad Request: /carga-datos/api/confirmar/
[2025-07-29 01:48:01,370] WARNING django.request - Not Found: /main.3c0e09960c9e6815b226.hot-update.json
[2025-07-29 01:48:01,601] WARNING django.request - Unauthorized: /carga-datos/api/confirmar/
[2025-07-29 01:48:01,603] WARNING django.request - Unauthorized: /carga-datos/api/confirmar/
[2025-07-29 01:48:22,557] INFO django.request - [angel] Previsualización cargada de 'Base de Datos BIA.xlsx' con 14 registros.
[2025-07-29 01:48:26,495] WARNING django.request - Bad Request: /carga-datos/api/confirmar/
[2025-07-29 01:48:26,504] WARNING django.request - Bad Request: /carga-datos/api/confirmar/
[2025-07-29 01:53:33,722] INFO django.request - [angel] Previsualización cargada de 'Base de Datos BIA.xlsx' con 14 registros.
[2025-07-29 02:05:01,093] INFO django.request - [angel] Previsualización cargada de 'Base de Datos BIA.xlsx' con 14 registros.
[2025-07-29 02:06:35,836] INFO django.request - [angel] Previsualización cargada de 'Base de Datos BIA.xlsx' con 14 registros.
[2025-07-29 02:07:08,251] WARNING django.request - Unauthorized: /api/token/
[2025-07-29 02:07:19,457] INFO django.request - [angel] Previsualización cargada de 'Base de Datos BIA.xlsx' con 14 registros.
[2025-07-29 02:26:01,394] INFO django.request - [angel] Previsualización cargada de 'Base de Datos BIA.xlsx' con 14 registros.
[2025-07-29 10:48:07,168] INFO django.request - [angel] Previsualización cargada de 'Base de Datos BIA.xlsx' con 14 registros.
[2025-07-29 10:48:07,726] ERROR django.request - Internal Server Error: /carga-datos/api/confirmar/
[2025-07-29 10:48:07,732] ERROR django.request - Internal Server Error: /carga-datos/api/confirmar/
[2025-07-29 10:48:28,645] INFO django.request - [angel] Previsualización cargada de 'Base de Datos BIA.xlsx' con 14 registros.
[2025-07-29 10:48:29,175] ERROR django.request - Internal Server Error: /carga-datos/api/confirmar/
[2025-07-29 10:48:29,179] ERROR django.request - Internal Server Error: /carga-datos/api/confirmar/
[2025-07-29 10:51:49,758] INFO django.request - [angel] Previsualización cargada de 'Base de Datos BIA.xlsx' con 14 registros.
[2025-07-29 10:51:50,296] ERROR django.request - Internal Server Error: /carga-datos/api/confirmar/
[2025-07-29 10:51:50,296] ERROR django.request - Internal Server Error: /carga-datos/api/confirmar/
[2025-07-29 11:21:38,297] INFO django.request - [angel] Previsualización cargada de 'Base de Datos BIA.xlsx' con 14 registros.
[2025-07-29 11:21:38,980] ERROR django.request - Internal Server Error: /carga-datos/api/confirmar/
[2025-07-29 11:21:38,980] ERROR django.request - Internal Server Error: /carga-datos/api/confirmar/
[2025-07-29 11:22:49,506] INFO django.request - [angel] Previsualización cargada de 'Base de Datos BIA.xlsx' con 14 registros.
[2025-07-29 11:22:50,205] ERROR django.request - Internal Server Error: /carga-datos/api/confirmar/
[2025-07-29 11:22:50,205] ERROR django.request - Internal Server Error: /carga-datos/api/confirmar/
[2025-07-29 11:27:46,235] INFO django.request - [angel] Previsualización cargada de 'Base de Datos BIA.xlsx' con 14 registros.
[2025-07-29 11:27:46,918] ERROR django.request - Internal Server Error: /carga-datos/api/confirmar/
[2025-07-29 11:27:46,927] ERROR django.request - Internal Server Error: /carga-datos/api/confirmar/
[2025-07-29 11:28:28,678] INFO django.request - [angel] Previsualización cargada de 'Base de Datos BIA.xlsx' con 14 registros.
[2025-07-29 11:28:29,363] ERROR django.request - Internal Server Error: /carga-datos/api/confirmar/
[2025-07-29 11:28:29,363] ERROR django.request - Internal Server Error: /carga-datos/api/confirmar/
[2025-07-29 11:49:54,694] ERROR django.request - Internal Server Error: /carga-datos/api/confirmar/
[2025-07-29 11:49:54,703] ERROR django.request - Internal Server Error: /carga-datos/api/confirmar/
[2025-07-29 11:50:19,953] ERROR django.request - Internal Server Error: /carga-datos/api/confirmar/
[2025-07-29 11:50:19,960] ERROR django.request - Internal Server Error: /carga-datos/api/confirmar/
[2025-07-29 11:50:41,947] INFO django.request - [angel] Previsualización cargada de 'Base de Datos BIA.xlsx' con 14 registros.
[2025-07-29 11:50:42,629] ERROR django.request - Internal Server Error: /carga-datos/api/confirmar/
[2025-07-29 11:50:42,629] ERROR django.request - Internal Server Error: /carga-datos/api/confirmar/
[2025-07-29 12:09:15,815] ERROR django.request - Internal Server Error: /carga-datos/api/confirmar/
[2025-07-29 12:09:15,854] ERROR django.request - Internal Server Error: /carga-datos/api/confirmar/
[2025-07-29 12:41:46,532] WARNING django.request - Unauthorized: /carga-datos/api/confirmar/
[2025-07-29 12:41:46,532] WARNING django.request - Unauthorized: /carga-datos/api/confirmar/
[2025-07-29 12:42:00,032] INFO django.request - [angel] Previsualización cargada de 'Base de Datos BIA.xlsx' con 14 registros.
[2025-07-29 12:42:00,715] ERROR django.request - Internal Server Error: /carga-datos/api/confirmar/
[2025-07-29 12:42:00,715] ERROR django.request - Internal Server Error: /carga-datos/api/confirmar/
[2025-07-29 13:05:35,727] INFO django.request - [angel] Previsualización cargada de 'Base de Datos BIA.xlsx' con 14 registros.
[2025-07-29 13:05:36,414] ERROR django.request - Internal Server Error: /carga-datos/api/confirmar/
[2025-07-29 13:05:36,415] ERROR django.request - Internal Server Error: /carga-datos/api/confirmar/
[2025-07-29 13:06:12,833] INFO django.request - [angel] Previsualización cargada de 'Base de Datos BIA.xlsx' con 14 registros.
[2025-07-29 13:06:13,510] ERROR django.request - Internal Server Error: /carga-datos/api/confirmar/
[2025-07-29 13:06:13,510] ERROR django.request - Internal Server Error: /carga-datos/api/confirmar/
[2025-07-29 13:16:21,390] ERROR django.request - Internal Server Error: /carga-datos/api/confirmar/
[2025-07-29 13:16:21,391] ERROR django.request - Internal Server Error: /carga-datos/api/confirmar/
[2025-07-29 13:16:39,754] INFO django.request - [angel] Previsualización cargada de 'Base de Datos BIA.xlsx' con 14 registros.
[2025-07-29 13:16:40,428] ERROR django.request - Internal Server Error: /carga-datos/api/confirmar/
[2025-07-29 13:16:40,437] ERROR django.request - Internal Server Error: /carga-datos/api/confirmar/
[2025-07-29 13:47:05,187] WARNING django.request - Unauthorized: /carga-datos/api/confirmar/
[2025-07-29 13:47:05,187] WARNING django.request - Unauthorized: /carga-datos/api/confirmar/
[2025-07-29 13:47:21,428] INFO django.request - [angel] Previsualización cargada de 'Base de Datos BIA.xlsx' con 14 registros.
[2025-07-29 13:47:22,144] ERROR django.request - Internal Server Error: /carga-datos/api/confirmar/
[2025-07-29 13:47:24,139] WARNING django.request - Not Found: /carga-datos/api/errores/
[2025-07-29 13:47:24,145] WARNING django.request - Not Found: /carga-datos/api/errores/
[2025-07-29 14:14:01,615] WARNING django.request - Not Found: /carga-datos/api/errores/
[2025-07-29 14:14:01,625] WARNING django.request - Not Found: /carga-datos/api/errores/
[2025-07-29 14:14:34,805] INFO django.request - [angel] Previsualización cargada de 'Base de Datos BIA.xlsx' con 14 registros.
[2025-07-29 14:14:35,335] WARNING django.request - Bad Request: /carga-datos/api/confirmar/
[2025-07-29 14:14:35,343] WARNING django.request - Bad Request: /carga-datos/api/confirmar/
[2025-07-29 14:15:43,260] INFO django.request - [angel] Previsualización cargada de 'Base de Datos BIA.xlsx' con 14 registros.
[2025-07-29 14:15:43,897] WARNING django.request - Bad Request: /carga-datos/api/confirmar/
[2025-07-29 14:15:43,899] WARNING django.request - Bad Request: /carga-datos/api/confirmar/
[2025-07-29 14:20:13,906] WARNING django.request - Bad Request: /carga-datos/api/confirmar/
[2025-07-29 14:20:13,912] WARNING django.request - Bad Request: /carga-datos/api/confirmar/
[2025-07-29 14:20:29,027] INFO django.request - [angel] Previsualización cargada de 'Base de Datos BIA.xlsx' con 14 registros.
[2025-07-29 14:20:29,561] WARNING django.request - Bad Request: /carga-datos/api/confirmar/
[2025-07-29 14:20:29,562] WARNING django.request - Bad Request: /carga-datos/api/confirmar/
[2025-07-29 15:01:08,020] INFO django.request - [angel] Previsualización cargada de 'Base de Datos BIA.xlsx' con 14 registros.
[2025-07-29 15:01:08,568] WARNING django.request - Bad Request: /carga-datos/api/confirmar/
[2025-07-29 15:01:08,569] WARNING django.request - Bad Request: /carga-datos/api/confirmar/
[2025-07-29 18:32:34,693] WARNING django.request - Unauthorized: /carga-datos/api/confirmar/
[2025-07-29 18:32:34,694] WARNING django.request - Unauthorized: /carga-datos/api/confirmar/
[2025-07-31 23:54:27,682] WARNING django.request - Not Found: /main.59b0581d7d470b235e73.hot-update.json
[2025-07-31 23:54:50,642] INFO django.request - [angel] Previsualización cargada de 'Base de Datos BIA.xlsx' con 14 registros.
[2025-07-31 23:54:51,380] ERROR django.request - Internal Server Error: /carga-datos/api/confirmar/
[2025-07-31 23:54:51,380] ERROR django.request - Internal Server Error: /carga-datos/api/confirmar/
[2025-08-01 00:20:35,788] ERROR django.request - Internal Server Error: /carga-datos/api/confirmar/
[2025-08-01 00:20:35,788] ERROR django.request - Internal Server Error: /carga-datos/api/confirmar/
[2025-08-01 00:20:35,984] WARNING django.request - Not Found: /main.b974d53e2c478aed9e3b.hot-update.json
[2025-08-01 00:21:20,965] INFO django.request - [angel] Previsualización cargada de 'Base de Datos BIA.xlsx' con 14 registros.
[2025-08-01 00:21:21,633] ERROR django.request - Internal Server Error: /carga-datos/api/confirmar/
[2025-08-01 00:21:21,663] ERROR django.request - Internal Server Error: /carga-datos/api/confirmar/
[2025-08-01 00:26:49,815] INFO django.request - [angel] Previsualización cargada de 'Base de Datos BIA.xlsx' con 14 registros.
[2025-08-01 00:26:50,547] ERROR django.request - Error en api_confirmar_carga:
Traceback (most recent call last):
  File "/Users/angel/Desktop/Proyecto Grupo BIA/GrupoBIA/venvGrupoBIA/lib/python3.12/site-packages/django/db/backends/utils.py", line 105, in _execute
    return self.cursor.execute(sql, params)
           ^^^^^^^^^^^^^^^^^^^^^^^^^^^^^^^^
psycopg2.errors.UniqueViolation: duplicate key value violates unique constraint "db_bia_pkey"
DETAIL:  Key (id_pago_unico)=(211816) already exists.


The above exception was the direct cause of the following exception:

Traceback (most recent call last):
  File "/Users/angel/Desktop/Proyecto Grupo BIA/GrupoBIA/proyecto_bia/proyecto_bia/carga_datos/views.py", line 213, in api_confirmar_carga
    BaseDeDatosBia.objects.bulk_create(registros, batch_size=100)
  File "/Users/angel/Desktop/Proyecto Grupo BIA/GrupoBIA/venvGrupoBIA/lib/python3.12/site-packages/django/db/models/manager.py", line 87, in manager_method
    return getattr(self.get_queryset(), name)(*args, **kwargs)
           ^^^^^^^^^^^^^^^^^^^^^^^^^^^^^^^^^^^^^^^^^^^^^^^^^^^
  File "/Users/angel/Desktop/Proyecto Grupo BIA/GrupoBIA/venvGrupoBIA/lib/python3.12/site-packages/django/db/models/query.py", line 818, in bulk_create
    returned_columns = self._batched_insert(
                       ^^^^^^^^^^^^^^^^^^^^^
  File "/Users/angel/Desktop/Proyecto Grupo BIA/GrupoBIA/venvGrupoBIA/lib/python3.12/site-packages/django/db/models/query.py", line 1875, in _batched_insert
    self._insert(
  File "/Users/angel/Desktop/Proyecto Grupo BIA/GrupoBIA/venvGrupoBIA/lib/python3.12/site-packages/django/db/models/query.py", line 1847, in _insert
    return query.get_compiler(using=using).execute_sql(returning_fields)
           ^^^^^^^^^^^^^^^^^^^^^^^^^^^^^^^^^^^^^^^^^^^^^^^^^^^^^^^^^^^^^
  File "/Users/angel/Desktop/Proyecto Grupo BIA/GrupoBIA/venvGrupoBIA/lib/python3.12/site-packages/django/db/models/sql/compiler.py", line 1836, in execute_sql
    cursor.execute(sql, params)
  File "/Users/angel/Desktop/Proyecto Grupo BIA/GrupoBIA/venvGrupoBIA/lib/python3.12/site-packages/django/db/backends/utils.py", line 122, in execute
    return super().execute(sql, params)
           ^^^^^^^^^^^^^^^^^^^^^^^^^^^^
  File "/Users/angel/Desktop/Proyecto Grupo BIA/GrupoBIA/venvGrupoBIA/lib/python3.12/site-packages/django/db/backends/utils.py", line 79, in execute
    return self._execute_with_wrappers(
           ^^^^^^^^^^^^^^^^^^^^^^^^^^^^
  File "/Users/angel/Desktop/Proyecto Grupo BIA/GrupoBIA/venvGrupoBIA/lib/python3.12/site-packages/django/db/backends/utils.py", line 92, in _execute_with_wrappers
    return executor(sql, params, many, context)
           ^^^^^^^^^^^^^^^^^^^^^^^^^^^^^^^^^^^^
  File "/Users/angel/Desktop/Proyecto Grupo BIA/GrupoBIA/venvGrupoBIA/lib/python3.12/site-packages/django/db/backends/utils.py", line 100, in _execute
    with self.db.wrap_database_errors:
         ^^^^^^^^^^^^^^^^^^^^^^^^^^^^
  File "/Users/angel/Desktop/Proyecto Grupo BIA/GrupoBIA/venvGrupoBIA/lib/python3.12/site-packages/django/db/utils.py", line 91, in __exit__
    raise dj_exc_value.with_traceback(traceback) from exc_value
  File "/Users/angel/Desktop/Proyecto Grupo BIA/GrupoBIA/venvGrupoBIA/lib/python3.12/site-packages/django/db/backends/utils.py", line 105, in _execute
    return self.cursor.execute(sql, params)
           ^^^^^^^^^^^^^^^^^^^^^^^^^^^^^^^^
django.db.utils.IntegrityError: duplicate key value violates unique constraint "db_bia_pkey"
DETAIL:  Key (id_pago_unico)=(211816) already exists.


[2025-08-01 00:26:50,547] ERROR django.request - Error en api_confirmar_carga:
Traceback (most recent call last):
  File "/Users/angel/Desktop/Proyecto Grupo BIA/GrupoBIA/venvGrupoBIA/lib/python3.12/site-packages/django/db/backends/utils.py", line 105, in _execute
    return self.cursor.execute(sql, params)
           ^^^^^^^^^^^^^^^^^^^^^^^^^^^^^^^^
psycopg2.errors.UniqueViolation: duplicate key value violates unique constraint "db_bia_pkey"
DETAIL:  Key (id_pago_unico)=(211816) already exists.


The above exception was the direct cause of the following exception:

Traceback (most recent call last):
  File "/Users/angel/Desktop/Proyecto Grupo BIA/GrupoBIA/proyecto_bia/proyecto_bia/carga_datos/views.py", line 213, in api_confirmar_carga
    BaseDeDatosBia.objects.bulk_create(registros, batch_size=100)
  File "/Users/angel/Desktop/Proyecto Grupo BIA/GrupoBIA/venvGrupoBIA/lib/python3.12/site-packages/django/db/models/manager.py", line 87, in manager_method
    return getattr(self.get_queryset(), name)(*args, **kwargs)
           ^^^^^^^^^^^^^^^^^^^^^^^^^^^^^^^^^^^^^^^^^^^^^^^^^^^
  File "/Users/angel/Desktop/Proyecto Grupo BIA/GrupoBIA/venvGrupoBIA/lib/python3.12/site-packages/django/db/models/query.py", line 818, in bulk_create
    returned_columns = self._batched_insert(
                       ^^^^^^^^^^^^^^^^^^^^^
  File "/Users/angel/Desktop/Proyecto Grupo BIA/GrupoBIA/venvGrupoBIA/lib/python3.12/site-packages/django/db/models/query.py", line 1875, in _batched_insert
    self._insert(
  File "/Users/angel/Desktop/Proyecto Grupo BIA/GrupoBIA/venvGrupoBIA/lib/python3.12/site-packages/django/db/models/query.py", line 1847, in _insert
    return query.get_compiler(using=using).execute_sql(returning_fields)
           ^^^^^^^^^^^^^^^^^^^^^^^^^^^^^^^^^^^^^^^^^^^^^^^^^^^^^^^^^^^^^
  File "/Users/angel/Desktop/Proyecto Grupo BIA/GrupoBIA/venvGrupoBIA/lib/python3.12/site-packages/django/db/models/sql/compiler.py", line 1836, in execute_sql
    cursor.execute(sql, params)
  File "/Users/angel/Desktop/Proyecto Grupo BIA/GrupoBIA/venvGrupoBIA/lib/python3.12/site-packages/django/db/backends/utils.py", line 122, in execute
    return super().execute(sql, params)
           ^^^^^^^^^^^^^^^^^^^^^^^^^^^^
  File "/Users/angel/Desktop/Proyecto Grupo BIA/GrupoBIA/venvGrupoBIA/lib/python3.12/site-packages/django/db/backends/utils.py", line 79, in execute
    return self._execute_with_wrappers(
           ^^^^^^^^^^^^^^^^^^^^^^^^^^^^
  File "/Users/angel/Desktop/Proyecto Grupo BIA/GrupoBIA/venvGrupoBIA/lib/python3.12/site-packages/django/db/backends/utils.py", line 92, in _execute_with_wrappers
    return executor(sql, params, many, context)
           ^^^^^^^^^^^^^^^^^^^^^^^^^^^^^^^^^^^^
  File "/Users/angel/Desktop/Proyecto Grupo BIA/GrupoBIA/venvGrupoBIA/lib/python3.12/site-packages/django/db/backends/utils.py", line 100, in _execute
    with self.db.wrap_database_errors:
         ^^^^^^^^^^^^^^^^^^^^^^^^^^^^
  File "/Users/angel/Desktop/Proyecto Grupo BIA/GrupoBIA/venvGrupoBIA/lib/python3.12/site-packages/django/db/utils.py", line 91, in __exit__
    raise dj_exc_value.with_traceback(traceback) from exc_value
  File "/Users/angel/Desktop/Proyecto Grupo BIA/GrupoBIA/venvGrupoBIA/lib/python3.12/site-packages/django/db/backends/utils.py", line 105, in _execute
    return self.cursor.execute(sql, params)
           ^^^^^^^^^^^^^^^^^^^^^^^^^^^^^^^^
django.db.utils.IntegrityError: duplicate key value violates unique constraint "db_bia_pkey"
DETAIL:  Key (id_pago_unico)=(211816) already exists.


[2025-08-01 00:26:50,548] ERROR django.request - Internal Server Error: /carga-datos/api/confirmar/
[2025-08-01 00:26:50,548] ERROR django.request - Internal Server Error: /carga-datos/api/confirmar/
[2025-08-01 00:27:15,398] ERROR django.request - Error en api_confirmar_carga:
Traceback (most recent call last):
  File "/Users/angel/Desktop/Proyecto Grupo BIA/GrupoBIA/venvGrupoBIA/lib/python3.12/site-packages/django/db/backends/utils.py", line 105, in _execute
    return self.cursor.execute(sql, params)
           ^^^^^^^^^^^^^^^^^^^^^^^^^^^^^^^^
psycopg2.errors.UniqueViolation: duplicate key value violates unique constraint "db_bia_pkey"
DETAIL:  Key (id_pago_unico)=(211816) already exists.


The above exception was the direct cause of the following exception:

Traceback (most recent call last):
  File "/Users/angel/Desktop/Proyecto Grupo BIA/GrupoBIA/proyecto_bia/proyecto_bia/carga_datos/views.py", line 213, in api_confirmar_carga
    BaseDeDatosBia.objects.bulk_create(registros, batch_size=100)
  File "/Users/angel/Desktop/Proyecto Grupo BIA/GrupoBIA/venvGrupoBIA/lib/python3.12/site-packages/django/db/models/manager.py", line 87, in manager_method
    return getattr(self.get_queryset(), name)(*args, **kwargs)
           ^^^^^^^^^^^^^^^^^^^^^^^^^^^^^^^^^^^^^^^^^^^^^^^^^^^
  File "/Users/angel/Desktop/Proyecto Grupo BIA/GrupoBIA/venvGrupoBIA/lib/python3.12/site-packages/django/db/models/query.py", line 818, in bulk_create
    returned_columns = self._batched_insert(
                       ^^^^^^^^^^^^^^^^^^^^^
  File "/Users/angel/Desktop/Proyecto Grupo BIA/GrupoBIA/venvGrupoBIA/lib/python3.12/site-packages/django/db/models/query.py", line 1875, in _batched_insert
    self._insert(
  File "/Users/angel/Desktop/Proyecto Grupo BIA/GrupoBIA/venvGrupoBIA/lib/python3.12/site-packages/django/db/models/query.py", line 1847, in _insert
    return query.get_compiler(using=using).execute_sql(returning_fields)
           ^^^^^^^^^^^^^^^^^^^^^^^^^^^^^^^^^^^^^^^^^^^^^^^^^^^^^^^^^^^^^
  File "/Users/angel/Desktop/Proyecto Grupo BIA/GrupoBIA/venvGrupoBIA/lib/python3.12/site-packages/django/db/models/sql/compiler.py", line 1836, in execute_sql
    cursor.execute(sql, params)
  File "/Users/angel/Desktop/Proyecto Grupo BIA/GrupoBIA/venvGrupoBIA/lib/python3.12/site-packages/django/db/backends/utils.py", line 122, in execute
    return super().execute(sql, params)
           ^^^^^^^^^^^^^^^^^^^^^^^^^^^^
  File "/Users/angel/Desktop/Proyecto Grupo BIA/GrupoBIA/venvGrupoBIA/lib/python3.12/site-packages/django/db/backends/utils.py", line 79, in execute
    return self._execute_with_wrappers(
           ^^^^^^^^^^^^^^^^^^^^^^^^^^^^
  File "/Users/angel/Desktop/Proyecto Grupo BIA/GrupoBIA/venvGrupoBIA/lib/python3.12/site-packages/django/db/backends/utils.py", line 92, in _execute_with_wrappers
    return executor(sql, params, many, context)
           ^^^^^^^^^^^^^^^^^^^^^^^^^^^^^^^^^^^^
  File "/Users/angel/Desktop/Proyecto Grupo BIA/GrupoBIA/venvGrupoBIA/lib/python3.12/site-packages/django/db/backends/utils.py", line 100, in _execute
    with self.db.wrap_database_errors:
         ^^^^^^^^^^^^^^^^^^^^^^^^^^^^
  File "/Users/angel/Desktop/Proyecto Grupo BIA/GrupoBIA/venvGrupoBIA/lib/python3.12/site-packages/django/db/utils.py", line 91, in __exit__
    raise dj_exc_value.with_traceback(traceback) from exc_value
  File "/Users/angel/Desktop/Proyecto Grupo BIA/GrupoBIA/venvGrupoBIA/lib/python3.12/site-packages/django/db/backends/utils.py", line 105, in _execute
    return self.cursor.execute(sql, params)
           ^^^^^^^^^^^^^^^^^^^^^^^^^^^^^^^^
django.db.utils.IntegrityError: duplicate key value violates unique constraint "db_bia_pkey"
DETAIL:  Key (id_pago_unico)=(211816) already exists.


[2025-08-01 00:27:15,398] ERROR django.request - Error en api_confirmar_carga:
Traceback (most recent call last):
  File "/Users/angel/Desktop/Proyecto Grupo BIA/GrupoBIA/venvGrupoBIA/lib/python3.12/site-packages/django/db/backends/utils.py", line 105, in _execute
    return self.cursor.execute(sql, params)
           ^^^^^^^^^^^^^^^^^^^^^^^^^^^^^^^^
psycopg2.errors.UniqueViolation: duplicate key value violates unique constraint "db_bia_pkey"
DETAIL:  Key (id_pago_unico)=(211816) already exists.


The above exception was the direct cause of the following exception:

Traceback (most recent call last):
  File "/Users/angel/Desktop/Proyecto Grupo BIA/GrupoBIA/proyecto_bia/proyecto_bia/carga_datos/views.py", line 213, in api_confirmar_carga
    BaseDeDatosBia.objects.bulk_create(registros, batch_size=100)
  File "/Users/angel/Desktop/Proyecto Grupo BIA/GrupoBIA/venvGrupoBIA/lib/python3.12/site-packages/django/db/models/manager.py", line 87, in manager_method
    return getattr(self.get_queryset(), name)(*args, **kwargs)
           ^^^^^^^^^^^^^^^^^^^^^^^^^^^^^^^^^^^^^^^^^^^^^^^^^^^
  File "/Users/angel/Desktop/Proyecto Grupo BIA/GrupoBIA/venvGrupoBIA/lib/python3.12/site-packages/django/db/models/query.py", line 818, in bulk_create
    returned_columns = self._batched_insert(
                       ^^^^^^^^^^^^^^^^^^^^^
  File "/Users/angel/Desktop/Proyecto Grupo BIA/GrupoBIA/venvGrupoBIA/lib/python3.12/site-packages/django/db/models/query.py", line 1875, in _batched_insert
    self._insert(
  File "/Users/angel/Desktop/Proyecto Grupo BIA/GrupoBIA/venvGrupoBIA/lib/python3.12/site-packages/django/db/models/query.py", line 1847, in _insert
    return query.get_compiler(using=using).execute_sql(returning_fields)
           ^^^^^^^^^^^^^^^^^^^^^^^^^^^^^^^^^^^^^^^^^^^^^^^^^^^^^^^^^^^^^
  File "/Users/angel/Desktop/Proyecto Grupo BIA/GrupoBIA/venvGrupoBIA/lib/python3.12/site-packages/django/db/models/sql/compiler.py", line 1836, in execute_sql
    cursor.execute(sql, params)
  File "/Users/angel/Desktop/Proyecto Grupo BIA/GrupoBIA/venvGrupoBIA/lib/python3.12/site-packages/django/db/backends/utils.py", line 122, in execute
    return super().execute(sql, params)
           ^^^^^^^^^^^^^^^^^^^^^^^^^^^^
  File "/Users/angel/Desktop/Proyecto Grupo BIA/GrupoBIA/venvGrupoBIA/lib/python3.12/site-packages/django/db/backends/utils.py", line 79, in execute
    return self._execute_with_wrappers(
           ^^^^^^^^^^^^^^^^^^^^^^^^^^^^
  File "/Users/angel/Desktop/Proyecto Grupo BIA/GrupoBIA/venvGrupoBIA/lib/python3.12/site-packages/django/db/backends/utils.py", line 92, in _execute_with_wrappers
    return executor(sql, params, many, context)
           ^^^^^^^^^^^^^^^^^^^^^^^^^^^^^^^^^^^^
  File "/Users/angel/Desktop/Proyecto Grupo BIA/GrupoBIA/venvGrupoBIA/lib/python3.12/site-packages/django/db/backends/utils.py", line 100, in _execute
    with self.db.wrap_database_errors:
         ^^^^^^^^^^^^^^^^^^^^^^^^^^^^
  File "/Users/angel/Desktop/Proyecto Grupo BIA/GrupoBIA/venvGrupoBIA/lib/python3.12/site-packages/django/db/utils.py", line 91, in __exit__
    raise dj_exc_value.with_traceback(traceback) from exc_value
  File "/Users/angel/Desktop/Proyecto Grupo BIA/GrupoBIA/venvGrupoBIA/lib/python3.12/site-packages/django/db/backends/utils.py", line 105, in _execute
    return self.cursor.execute(sql, params)
           ^^^^^^^^^^^^^^^^^^^^^^^^^^^^^^^^
django.db.utils.IntegrityError: duplicate key value violates unique constraint "db_bia_pkey"
DETAIL:  Key (id_pago_unico)=(211816) already exists.


[2025-08-01 00:27:15,399] ERROR django.request - Internal Server Error: /carga-datos/api/confirmar/
[2025-08-01 00:27:15,399] ERROR django.request - Internal Server Error: /carga-datos/api/confirmar/
[2025-08-01 02:05:01,006] WARNING django.request - Not Found: /favicon.ico
[2025-08-01 02:07:20,782] WARNING django.request - Unauthorized: /api/token/
[2025-08-03 20:05:34,588] INFO django.request - [angel] Faltan columnas en archivo 'datos_para_prueba_de_carga.xlsx': ['entidadinterna', 'nombre_apellido', 'fecha_apertura']
[2025-08-03 20:05:34,590] WARNING django.request - Bad Request: /carga-datos/api/
[2025-08-03 20:09:13,457] INFO django.request - [angel] Previsualizaci�n cargada de 'datos_para_prueba_de_carga.xlsx' con 6 registros.
[2025-08-03 20:09:15,265] ERROR django.request - Error en api_confirmar_carga:
Traceback (most recent call last):
  File "C:\Users\moreiracristian\Documents\moreira\GrupoBIA\venvbia\Lib\site-packages\django\db\backends\utils.py", line 105, in _execute
    return self.cursor.execute(sql, params)
           ^^^^^^^^^^^^^^^^^^^^^^^^^^^^^^^^
psycopg2.errors.UniqueViolation: duplicate key value violates unique constraint "db_bia_pkey"
DETAIL:  Key (id_pago_unico)=(125478) already exists.


The above exception was the direct cause of the following exception:

Traceback (most recent call last):
  File "C:\Users\moreiracristian\Documents\moreira\GrupoBIA\proyecto_bia\proyecto_bia\carga_datos\views.py", line 213, in api_confirmar_carga
    BaseDeDatosBia.objects.bulk_create(registros, batch_size=100)
  File "C:\Users\moreiracristian\Documents\moreira\GrupoBIA\venvbia\Lib\site-packages\django\db\models\manager.py", line 87, in manager_method
    return getattr(self.get_queryset(), name)(*args, **kwargs)
           ^^^^^^^^^^^^^^^^^^^^^^^^^^^^^^^^^^^^^^^^^^^^^^^^^^^
  File "C:\Users\moreiracristian\Documents\moreira\GrupoBIA\venvbia\Lib\site-packages\django\db\models\query.py", line 818, in bulk_create
    returned_columns = self._batched_insert(
                       ^^^^^^^^^^^^^^^^^^^^^
  File "C:\Users\moreiracristian\Documents\moreira\GrupoBIA\venvbia\Lib\site-packages\django\db\models\query.py", line 1875, in _batched_insert
    self._insert(
  File "C:\Users\moreiracristian\Documents\moreira\GrupoBIA\venvbia\Lib\site-packages\django\db\models\query.py", line 1847, in _insert
    return query.get_compiler(using=using).execute_sql(returning_fields)
           ^^^^^^^^^^^^^^^^^^^^^^^^^^^^^^^^^^^^^^^^^^^^^^^^^^^^^^^^^^^^^
  File "C:\Users\moreiracristian\Documents\moreira\GrupoBIA\venvbia\Lib\site-packages\django\db\models\sql\compiler.py", line 1836, in execute_sql
    cursor.execute(sql, params)
  File "C:\Users\moreiracristian\Documents\moreira\GrupoBIA\venvbia\Lib\site-packages\django\db\backends\utils.py", line 122, in execute
    return super().execute(sql, params)
           ^^^^^^^^^^^^^^^^^^^^^^^^^^^^
  File "C:\Users\moreiracristian\Documents\moreira\GrupoBIA\venvbia\Lib\site-packages\django\db\backends\utils.py", line 79, in execute
    return self._execute_with_wrappers(
           ^^^^^^^^^^^^^^^^^^^^^^^^^^^^
  File "C:\Users\moreiracristian\Documents\moreira\GrupoBIA\venvbia\Lib\site-packages\django\db\backends\utils.py", line 92, in _execute_with_wrappers
    return executor(sql, params, many, context)
           ^^^^^^^^^^^^^^^^^^^^^^^^^^^^^^^^^^^^
  File "C:\Users\moreiracristian\Documents\moreira\GrupoBIA\venvbia\Lib\site-packages\django\db\backends\utils.py", line 100, in _execute
    with self.db.wrap_database_errors:
         ^^^^^^^^^^^^^^^^^^^^^^^^^^^^
  File "C:\Users\moreiracristian\Documents\moreira\GrupoBIA\venvbia\Lib\site-packages\django\db\utils.py", line 91, in __exit__
    raise dj_exc_value.with_traceback(traceback) from exc_value
  File "C:\Users\moreiracristian\Documents\moreira\GrupoBIA\venvbia\Lib\site-packages\django\db\backends\utils.py", line 105, in _execute
    return self.cursor.execute(sql, params)
           ^^^^^^^^^^^^^^^^^^^^^^^^^^^^^^^^
django.db.utils.IntegrityError: duplicate key value violates unique constraint "db_bia_pkey"
DETAIL:  Key (id_pago_unico)=(125478) already exists.


[2025-08-03 20:09:15,273] ERROR django.request - Internal Server Error: /carga-datos/api/confirmar/
[2025-08-03 20:09:17,733] WARNING django.request - Not Found: /carga-datos/api/errores/
[2025-08-03 20:09:18,523] WARNING django.request - Not Found: /carga-datos/api/errores/
[2025-08-04 01:42:41,056] WARNING django.request - Not Found: /api/certificado/generar/
[2025-08-04 01:42:57,441] ERROR django.request - Internal Server Error: /api/certificado/generar/
Traceback (most recent call last):
  File "C:\Users\moreiracristian\Documents\moreira\GrupoBIA\venvbia\Lib\site-packages\django\db\models\query.py", line 948, in get_or_create
    return self.get(**kwargs), False
           ^^^^^^^^^^^^^^^^^^
  File "C:\Users\moreiracristian\Documents\moreira\GrupoBIA\venvbia\Lib\site-packages\django\db\models\query.py", line 649, in get
    raise self.model.DoesNotExist(
certificado_ldd.models.Certificate.DoesNotExist: Certificate matching query does not exist.

During handling of the above exception, another exception occurred:

Traceback (most recent call last):
  File "C:\Users\moreiracristian\Documents\moreira\GrupoBIA\venvbia\Lib\site-packages\django\db\backends\base\base.py", line 303, in _commit
    return self.connection.commit()
           ^^^^^^^^^^^^^^^^^^^^^^^^
psycopg2.errors.ForeignKeyViolation: insert or update on table "certificate" violates foreign key constraint "certificate_client_id_f53aa671_fk_certifica"
DETAIL:  Key (client_id)=(125483) is not present in table "certificado_ldd_basededatosbia".


The above exception was the direct cause of the following exception:

Traceback (most recent call last):
  File "C:\Users\moreiracristian\Documents\moreira\GrupoBIA\venvbia\Lib\site-packages\django\core\handlers\exception.py", line 55, in inner
    response = get_response(request)
               ^^^^^^^^^^^^^^^^^^^^^
  File "C:\Users\moreiracristian\Documents\moreira\GrupoBIA\venvbia\Lib\site-packages\django\core\handlers\base.py", line 197, in _get_response
    response = wrapped_callback(request, *callback_args, **callback_kwargs)
               ^^^^^^^^^^^^^^^^^^^^^^^^^^^^^^^^^^^^^^^^^^^^^^^^^^^^^^^^^^^^
  File "C:\Users\moreiracristian\Documents\moreira\GrupoBIA\venvbia\Lib\site-packages\django\views\decorators\csrf.py", line 65, in _view_wrapper
    return view_func(request, *args, **kwargs)
           ^^^^^^^^^^^^^^^^^^^^^^^^^^^^^^^^^^^
  File "C:\Users\moreiracristian\Documents\moreira\GrupoBIA\proyecto_bia\proyecto_bia\certificado_ldd\views.py", line 111, in api_generar_certificado
    certificate, created = Certificate.objects.get_or_create(client=registro)
                           ^^^^^^^^^^^^^^^^^^^^^^^^^^^^^^^^^^^^^^^^^^^^^^^^^^
  File "C:\Users\moreiracristian\Documents\moreira\GrupoBIA\venvbia\Lib\site-packages\django\db\models\manager.py", line 87, in manager_method
    return getattr(self.get_queryset(), name)(*args, **kwargs)
           ^^^^^^^^^^^^^^^^^^^^^^^^^^^^^^^^^^^^^^^^^^^^^^^^^^^
  File "C:\Users\moreiracristian\Documents\moreira\GrupoBIA\venvbia\Lib\site-packages\django\db\models\query.py", line 953, in get_or_create
    with transaction.atomic(using=self.db):
         ^^^^^^^^^^^^^^^^^^^^^^^^^^^^^^^^^
  File "C:\Users\moreiracristian\Documents\moreira\GrupoBIA\venvbia\Lib\site-packages\django\db\transaction.py", line 263, in __exit__
    connection.commit()
  File "C:\Users\moreiracristian\Documents\moreira\GrupoBIA\venvbia\Lib\site-packages\django\utils\asyncio.py", line 26, in inner
    return func(*args, **kwargs)
           ^^^^^^^^^^^^^^^^^^^^^
  File "C:\Users\moreiracristian\Documents\moreira\GrupoBIA\venvbia\Lib\site-packages\django\db\backends\base\base.py", line 327, in commit
    self._commit()
  File "C:\Users\moreiracristian\Documents\moreira\GrupoBIA\venvbia\Lib\site-packages\django\db\backends\base\base.py", line 302, in _commit
    with debug_transaction(self, "COMMIT"), self.wrap_database_errors:
                                            ^^^^^^^^^^^^^^^^^^^^^^^^^
  File "C:\Users\moreiracristian\Documents\moreira\GrupoBIA\venvbia\Lib\site-packages\django\db\utils.py", line 91, in __exit__
    raise dj_exc_value.with_traceback(traceback) from exc_value
  File "C:\Users\moreiracristian\Documents\moreira\GrupoBIA\venvbia\Lib\site-packages\django\db\backends\base\base.py", line 303, in _commit
    return self.connection.commit()
           ^^^^^^^^^^^^^^^^^^^^^^^^
django.db.utils.IntegrityError: insert or update on table "certificate" violates foreign key constraint "certificate_client_id_f53aa671_fk_certifica"
DETAIL:  Key (client_id)=(125483) is not present in table "certificado_ldd_basededatosbia".

[2025-08-04 01:43:51,824] WARNING django.request - Not Found: /api/certificado/generar/
[2025-08-04 01:44:00,079] ERROR django.request - Internal Server Error: /api/certificado/generar/
Traceback (most recent call last):
  File "C:\Users\moreiracristian\Documents\moreira\GrupoBIA\venvbia\Lib\site-packages\django\db\models\query.py", line 948, in get_or_create
    return self.get(**kwargs), False
           ^^^^^^^^^^^^^^^^^^
  File "C:\Users\moreiracristian\Documents\moreira\GrupoBIA\venvbia\Lib\site-packages\django\db\models\query.py", line 649, in get
    raise self.model.DoesNotExist(
certificado_ldd.models.Certificate.DoesNotExist: Certificate matching query does not exist.

During handling of the above exception, another exception occurred:

Traceback (most recent call last):
  File "C:\Users\moreiracristian\Documents\moreira\GrupoBIA\venvbia\Lib\site-packages\django\db\backends\base\base.py", line 303, in _commit
    return self.connection.commit()
           ^^^^^^^^^^^^^^^^^^^^^^^^
psycopg2.errors.ForeignKeyViolation: insert or update on table "certificate" violates foreign key constraint "certificate_client_id_f53aa671_fk_certifica"
DETAIL:  Key (client_id)=(125483) is not present in table "certificado_ldd_basededatosbia".


The above exception was the direct cause of the following exception:

Traceback (most recent call last):
  File "C:\Users\moreiracristian\Documents\moreira\GrupoBIA\venvbia\Lib\site-packages\django\core\handlers\exception.py", line 55, in inner
    response = get_response(request)
               ^^^^^^^^^^^^^^^^^^^^^
  File "C:\Users\moreiracristian\Documents\moreira\GrupoBIA\venvbia\Lib\site-packages\django\core\handlers\base.py", line 197, in _get_response
    response = wrapped_callback(request, *callback_args, **callback_kwargs)
               ^^^^^^^^^^^^^^^^^^^^^^^^^^^^^^^^^^^^^^^^^^^^^^^^^^^^^^^^^^^^
  File "C:\Users\moreiracristian\Documents\moreira\GrupoBIA\venvbia\Lib\site-packages\django\views\decorators\csrf.py", line 65, in _view_wrapper
    return view_func(request, *args, **kwargs)
           ^^^^^^^^^^^^^^^^^^^^^^^^^^^^^^^^^^^
  File "C:\Users\moreiracristian\Documents\moreira\GrupoBIA\proyecto_bia\proyecto_bia\certificado_ldd\views.py", line 111, in api_generar_certificado
    certificate, created = Certificate.objects.get_or_create(client=registro)
                           ^^^^^^^^^^^^^^^^^^^^^^^^^^^^^^^^^^^^^^^^^^^^^^^^^^
  File "C:\Users\moreiracristian\Documents\moreira\GrupoBIA\venvbia\Lib\site-packages\django\db\models\manager.py", line 87, in manager_method
    return getattr(self.get_queryset(), name)(*args, **kwargs)
           ^^^^^^^^^^^^^^^^^^^^^^^^^^^^^^^^^^^^^^^^^^^^^^^^^^^
  File "C:\Users\moreiracristian\Documents\moreira\GrupoBIA\venvbia\Lib\site-packages\django\db\models\query.py", line 953, in get_or_create
    with transaction.atomic(using=self.db):
         ^^^^^^^^^^^^^^^^^^^^^^^^^^^^^^^^^
  File "C:\Users\moreiracristian\Documents\moreira\GrupoBIA\venvbia\Lib\site-packages\django\db\transaction.py", line 263, in __exit__
    connection.commit()
  File "C:\Users\moreiracristian\Documents\moreira\GrupoBIA\venvbia\Lib\site-packages\django\utils\asyncio.py", line 26, in inner
    return func(*args, **kwargs)
           ^^^^^^^^^^^^^^^^^^^^^
  File "C:\Users\moreiracristian\Documents\moreira\GrupoBIA\venvbia\Lib\site-packages\django\db\backends\base\base.py", line 327, in commit
    self._commit()
  File "C:\Users\moreiracristian\Documents\moreira\GrupoBIA\venvbia\Lib\site-packages\django\db\backends\base\base.py", line 302, in _commit
    with debug_transaction(self, "COMMIT"), self.wrap_database_errors:
                                            ^^^^^^^^^^^^^^^^^^^^^^^^^
  File "C:\Users\moreiracristian\Documents\moreira\GrupoBIA\venvbia\Lib\site-packages\django\db\utils.py", line 91, in __exit__
    raise dj_exc_value.with_traceback(traceback) from exc_value
  File "C:\Users\moreiracristian\Documents\moreira\GrupoBIA\venvbia\Lib\site-packages\django\db\backends\base\base.py", line 303, in _commit
    return self.connection.commit()
           ^^^^^^^^^^^^^^^^^^^^^^^^
django.db.utils.IntegrityError: insert or update on table "certificate" violates foreign key constraint "certificate_client_id_f53aa671_fk_certifica"
DETAIL:  Key (client_id)=(125483) is not present in table "certificado_ldd_basededatosbia".

[2025-08-04 01:46:45,460] WARNING django.request - Not Found: /api/certificado/generar/
[2025-08-04 20:56:48,922] WARNING django.request - Not Found: /main.a1f3303e59ed15d2253d.hot-update.json
[2025-08-04 21:29:34,995] WARNING django.request - Not Found: /api/certificado/generar/
[2025-08-04 21:50:53,117] WARNING django.request - Not Found: /api/certificado/generar/
[2025-08-04 21:51:10,695] ERROR django.request - Internal Server Error: /api/certificado/generar/
Traceback (most recent call last):
  File "C:\Users\moreiracristian\Documents\moreira\GrupoBIA\venvbia\Lib\site-packages\django\db\backends\utils.py", line 105, in _execute
    return self.cursor.execute(sql, params)
           ^^^^^^^^^^^^^^^^^^^^^^^^^^^^^^^^
psycopg2.errors.UndefinedColumn: column db_bia.entidadinterna_id does not exist
LINE 1: ...b_bia"."propietario", "db_bia"."entidadoriginal", "db_bia"."...
                                                             ^
HINT:  Perhaps you meant to reference the column "db_bia.entidadinterna".


The above exception was the direct cause of the following exception:

Traceback (most recent call last):
  File "C:\Users\moreiracristian\Documents\moreira\GrupoBIA\venvbia\Lib\site-packages\django\core\handlers\exception.py", line 55, in inner
    response = get_response(request)
               ^^^^^^^^^^^^^^^^^^^^^
  File "C:\Users\moreiracristian\Documents\moreira\GrupoBIA\venvbia\Lib\site-packages\django\core\handlers\base.py", line 197, in _get_response
    response = wrapped_callback(request, *callback_args, **callback_kwargs)
               ^^^^^^^^^^^^^^^^^^^^^^^^^^^^^^^^^^^^^^^^^^^^^^^^^^^^^^^^^^^^
  File "C:\Users\moreiracristian\Documents\moreira\GrupoBIA\venvbia\Lib\site-packages\django\views\decorators\csrf.py", line 65, in _view_wrapper
    return view_func(request, *args, **kwargs)
           ^^^^^^^^^^^^^^^^^^^^^^^^^^^^^^^^^^^
  File "C:\Users\moreiracristian\Documents\moreira\GrupoBIA\proyecto_bia\proyecto_bia\certificado_ldd\views.py", line 127, in api_generar_certificado
    for p in pendientes
             ^^^^^^^^^^
  File "C:\Users\moreiracristian\Documents\moreira\GrupoBIA\venvbia\Lib\site-packages\django\db\models\query.py", line 400, in __iter__
    self._fetch_all()
  File "C:\Users\moreiracristian\Documents\moreira\GrupoBIA\venvbia\Lib\site-packages\django\db\models\query.py", line 1928, in _fetch_all
    self._result_cache = list(self._iterable_class(self))
                         ^^^^^^^^^^^^^^^^^^^^^^^^^^^^^^^^
  File "C:\Users\moreiracristian\Documents\moreira\GrupoBIA\venvbia\Lib\site-packages\django\db\models\query.py", line 91, in __iter__
    results = compiler.execute_sql(
              ^^^^^^^^^^^^^^^^^^^^^
  File "C:\Users\moreiracristian\Documents\moreira\GrupoBIA\venvbia\Lib\site-packages\django\db\models\sql\compiler.py", line 1574, in execute_sql
    cursor.execute(sql, params)
  File "C:\Users\moreiracristian\Documents\moreira\GrupoBIA\venvbia\Lib\site-packages\django\db\backends\utils.py", line 122, in execute
    return super().execute(sql, params)
           ^^^^^^^^^^^^^^^^^^^^^^^^^^^^
  File "C:\Users\moreiracristian\Documents\moreira\GrupoBIA\venvbia\Lib\site-packages\django\db\backends\utils.py", line 79, in execute
    return self._execute_with_wrappers(
           ^^^^^^^^^^^^^^^^^^^^^^^^^^^^
  File "C:\Users\moreiracristian\Documents\moreira\GrupoBIA\venvbia\Lib\site-packages\django\db\backends\utils.py", line 92, in _execute_with_wrappers
    return executor(sql, params, many, context)
           ^^^^^^^^^^^^^^^^^^^^^^^^^^^^^^^^^^^^
  File "C:\Users\moreiracristian\Documents\moreira\GrupoBIA\venvbia\Lib\site-packages\django\db\backends\utils.py", line 100, in _execute
    with self.db.wrap_database_errors:
         ^^^^^^^^^^^^^^^^^^^^^^^^^^^^
  File "C:\Users\moreiracristian\Documents\moreira\GrupoBIA\venvbia\Lib\site-packages\django\db\utils.py", line 91, in __exit__
    raise dj_exc_value.with_traceback(traceback) from exc_value
  File "C:\Users\moreiracristian\Documents\moreira\GrupoBIA\venvbia\Lib\site-packages\django\db\backends\utils.py", line 105, in _execute
    return self.cursor.execute(sql, params)
           ^^^^^^^^^^^^^^^^^^^^^^^^^^^^^^^^
django.db.utils.ProgrammingError: column db_bia.entidadinterna_id does not exist
LINE 1: ...b_bia"."propietario", "db_bia"."entidadoriginal", "db_bia"."...
                                                             ^
HINT:  Perhaps you meant to reference the column "db_bia.entidadinterna".

[2025-08-05 01:23:24,518] WARNING django.request - Not Found: /api/certificado/generar/
[2025-08-04 02:07:26,528] WARNING django.request - Not Found: /main.0c522d0e3c1f963d6858.hot-update.json
[2025-08-04 02:17:40,704] WARNING django.request - Not Found: /api/certificado/generar/
[2025-08-04 02:24:17,930] WARNING django.request - Not Found: /main.22cbbf7d63d0fd71cb95.hot-update.json
[2025-08-04 02:30:13,879] WARNING django.request - Not Found: /api/certificado/generar/
[2025-08-04 02:30:16,770] WARNING django.request - Not Found: /api/certificado/generar/
[2025-08-04 02:30:18,068] WARNING django.request - Not Found: /api/certificado/generar/
[2025-08-04 02:30:19,230] WARNING django.request - Not Found: /api/certificado/generar/
[2025-08-04 02:30:20,380] WARNING django.request - Not Found: /api/certificado/generar/
[2025-08-04 02:33:00,516] WARNING django.request - Not Found: /main.30ae183483cb406a8980.hot-update.json
[2025-08-04 02:35:22,256] WARNING django.request - Not Found: /main.0d0c10f25c83d43b0c6b.hot-update.json
[2025-08-04 11:19:08,969] WARNING django.request - Not Found: /main.991b60f64bb8ff71245d.hot-update.json
[2025-08-04 15:49:44,802] WARNING django.request - Not Found: /main.968a47e767cd42dbdd45.hot-update.json
[2025-08-04 16:06:37,342] WARNING django.request - Not Found: /main.fbdab7954feab8e2e83f.hot-update.json
[2025-08-04 16:35:12,292] WARNING django.request - Not Found: /main.67d5cf6d1d6204636619.hot-update.json
[2025-08-04 16:35:12,330] WARNING django.request - Not Found: /main.67d5cf6d1d6204636619.hot-update.json
[2025-08-04 16:36:56,065] WARNING django.request - Not Found: /main.7a9edadb47347035b968.hot-update.json
[2025-08-04 16:36:56,077] WARNING django.request - Not Found: /main.7a9edadb47347035b968.hot-update.json
[2025-08-04 17:10:29,076] WARNING django.request - Not Found: /main.84d9c17d01e31b998694.hot-update.json
[2025-08-04 17:17:46,031] WARNING django.request - Not Found: /main.226ef6a12bf44f11c405.hot-update.json
[2025-08-04 17:17:46,083] WARNING django.request - Not Found: /main.226ef6a12bf44f11c405.hot-update.json
[2025-08-04 17:17:46,116] WARNING django.request - Not Found: /main.226ef6a12bf44f11c405.hot-update.json
[2025-08-04 17:35:34,183] WARNING django.request - Not Found: /main.292ddff496217622993e.hot-update.json
[2025-08-04 17:35:34,999] WARNING django.request - Not Found: /main.292ddff496217622993e.hot-update.json
[2025-08-04 17:35:35,015] WARNING django.request - Not Found: /main.292ddff496217622993e.hot-update.json
[2025-08-04 17:37:56,181] WARNING django.request - Unauthorized: /carga-datos/api/
[2025-08-04 18:42:20,961] WARNING django.request - Not Found: /main.27a5245a3307d6a44efb.hot-update.json
[2025-08-04 18:42:22,933] WARNING django.request - Not Found: /main.27a5245a3307d6a44efb.hot-update.json
[2025-08-04 18:42:22,943] WARNING django.request - Not Found: /main.27a5245a3307d6a44efb.hot-update.json
[2025-08-04 18:42:22,960] WARNING django.request - Not Found: /main.27a5245a3307d6a44efb.hot-update.json
[2025-08-04 18:42:23,072] WARNING django.request - Not Found: /main.27a5245a3307d6a44efb.hot-update.json
[2025-08-04 18:50:08,039] WARNING django.request - Not Found: /main.c305489c3a2d0d354657.hot-update.json
[2025-08-04 18:50:08,046] WARNING django.request - Not Found: /main.c305489c3a2d0d354657.hot-update.json
[2025-08-04 18:50:08,054] WARNING django.request - Not Found: /main.c305489c3a2d0d354657.hot-update.json
[2025-08-04 18:50:08,064] WARNING django.request - Not Found: /main.c305489c3a2d0d354657.hot-update.json
[2025-08-04 18:50:08,068] WARNING django.request - Not Found: /main.c305489c3a2d0d354657.hot-update.json
[2025-08-04 19:19:28,117] WARNING django.request - Not Found: /api/certificado/generar/
[2025-08-06 12:47:13,557] WARNING django.request - Not Found: /api/certificado/generar/
[2025-08-06 13:11:42,183] WARNING django.request - Bad Request: /api/token/
[2025-08-06 13:15:48,077] WARNING django.request - Not Found: /main.065aac45677dac01656b.hot-update.json
[2025-08-06 13:22:06,225] WARNING django.request - Not Found: /main.2e500846b676b3b21bcc.hot-update.json
[2025-08-06 13:26:57,090] WARNING django.request - Not Found: /main.66c073b34206e076ada7.hot-update.json
[2025-08-06 13:38:02,057] WARNING django.request - Not Found: /main.227ebaee7c5d0fadb784.hot-update.json
[2025-08-06 13:38:02,063] WARNING django.request - Not Found: /main.227ebaee7c5d0fadb784.hot-update.json
[2025-08-06 13:38:02,080] WARNING django.request - Not Found: /main.227ebaee7c5d0fadb784.hot-update.json
[2025-08-06 13:40:46,111] WARNING django.request - Not Found: /api/certificado/generar/
[2025-08-06 13:46:39,509] WARNING django.request - Unauthorized: /carga-datos/api/
[2025-08-06 13:47:12,471] WARNING django.request - Not Found: /api/certificado/generar/
[2025-08-06 13:47:47,894] INFO django.request - [angel] Previsualización cargada de 'Base de Datos BIA.xlsx' con 14 registros.
[2025-08-06 13:47:48,653] ERROR django.request - Error en api_confirmar_carga:
Traceback (most recent call last):
  File "/Users/angel/Desktop/Proyecto Grupo BIA/GrupoBIA/venvGrupoBIA/lib/python3.12/site-packages/django/db/backends/utils.py", line 105, in _execute
    return self.cursor.execute(sql, params)
           ^^^^^^^^^^^^^^^^^^^^^^^^^^^^^^^^
psycopg2.errors.UniqueViolation: duplicate key value violates unique constraint "db_bia_pkey"
DETAIL:  Key (id_pago_unico)=(211816) already exists.


The above exception was the direct cause of the following exception:

Traceback (most recent call last):
  File "/Users/angel/Desktop/Proyecto Grupo BIA/GrupoBIA/proyecto_bia/proyecto_bia/carga_datos/views.py", line 213, in api_confirmar_carga
    BaseDeDatosBia.objects.bulk_create(registros, batch_size=100)
  File "/Users/angel/Desktop/Proyecto Grupo BIA/GrupoBIA/venvGrupoBIA/lib/python3.12/site-packages/django/db/models/manager.py", line 87, in manager_method
    return getattr(self.get_queryset(), name)(*args, **kwargs)
           ^^^^^^^^^^^^^^^^^^^^^^^^^^^^^^^^^^^^^^^^^^^^^^^^^^^
  File "/Users/angel/Desktop/Proyecto Grupo BIA/GrupoBIA/venvGrupoBIA/lib/python3.12/site-packages/django/db/models/query.py", line 818, in bulk_create
    returned_columns = self._batched_insert(
                       ^^^^^^^^^^^^^^^^^^^^^
  File "/Users/angel/Desktop/Proyecto Grupo BIA/GrupoBIA/venvGrupoBIA/lib/python3.12/site-packages/django/db/models/query.py", line 1875, in _batched_insert
    self._insert(
  File "/Users/angel/Desktop/Proyecto Grupo BIA/GrupoBIA/venvGrupoBIA/lib/python3.12/site-packages/django/db/models/query.py", line 1847, in _insert
    return query.get_compiler(using=using).execute_sql(returning_fields)
           ^^^^^^^^^^^^^^^^^^^^^^^^^^^^^^^^^^^^^^^^^^^^^^^^^^^^^^^^^^^^^
  File "/Users/angel/Desktop/Proyecto Grupo BIA/GrupoBIA/venvGrupoBIA/lib/python3.12/site-packages/django/db/models/sql/compiler.py", line 1836, in execute_sql
    cursor.execute(sql, params)
  File "/Users/angel/Desktop/Proyecto Grupo BIA/GrupoBIA/venvGrupoBIA/lib/python3.12/site-packages/django/db/backends/utils.py", line 122, in execute
    return super().execute(sql, params)
           ^^^^^^^^^^^^^^^^^^^^^^^^^^^^
  File "/Users/angel/Desktop/Proyecto Grupo BIA/GrupoBIA/venvGrupoBIA/lib/python3.12/site-packages/django/db/backends/utils.py", line 79, in execute
    return self._execute_with_wrappers(
           ^^^^^^^^^^^^^^^^^^^^^^^^^^^^
  File "/Users/angel/Desktop/Proyecto Grupo BIA/GrupoBIA/venvGrupoBIA/lib/python3.12/site-packages/django/db/backends/utils.py", line 92, in _execute_with_wrappers
    return executor(sql, params, many, context)
           ^^^^^^^^^^^^^^^^^^^^^^^^^^^^^^^^^^^^
  File "/Users/angel/Desktop/Proyecto Grupo BIA/GrupoBIA/venvGrupoBIA/lib/python3.12/site-packages/django/db/backends/utils.py", line 100, in _execute
    with self.db.wrap_database_errors:
         ^^^^^^^^^^^^^^^^^^^^^^^^^^^^
  File "/Users/angel/Desktop/Proyecto Grupo BIA/GrupoBIA/venvGrupoBIA/lib/python3.12/site-packages/django/db/utils.py", line 91, in __exit__
    raise dj_exc_value.with_traceback(traceback) from exc_value
  File "/Users/angel/Desktop/Proyecto Grupo BIA/GrupoBIA/venvGrupoBIA/lib/python3.12/site-packages/django/db/backends/utils.py", line 105, in _execute
    return self.cursor.execute(sql, params)
           ^^^^^^^^^^^^^^^^^^^^^^^^^^^^^^^^
django.db.utils.IntegrityError: duplicate key value violates unique constraint "db_bia_pkey"
DETAIL:  Key (id_pago_unico)=(211816) already exists.


[2025-08-06 13:47:48,653] ERROR django.request - Error en api_confirmar_carga:
Traceback (most recent call last):
  File "/Users/angel/Desktop/Proyecto Grupo BIA/GrupoBIA/venvGrupoBIA/lib/python3.12/site-packages/django/db/backends/utils.py", line 105, in _execute
    return self.cursor.execute(sql, params)
           ^^^^^^^^^^^^^^^^^^^^^^^^^^^^^^^^
psycopg2.errors.UniqueViolation: duplicate key value violates unique constraint "db_bia_pkey"
DETAIL:  Key (id_pago_unico)=(211816) already exists.


The above exception was the direct cause of the following exception:

Traceback (most recent call last):
  File "/Users/angel/Desktop/Proyecto Grupo BIA/GrupoBIA/proyecto_bia/proyecto_bia/carga_datos/views.py", line 213, in api_confirmar_carga
    BaseDeDatosBia.objects.bulk_create(registros, batch_size=100)
  File "/Users/angel/Desktop/Proyecto Grupo BIA/GrupoBIA/venvGrupoBIA/lib/python3.12/site-packages/django/db/models/manager.py", line 87, in manager_method
    return getattr(self.get_queryset(), name)(*args, **kwargs)
           ^^^^^^^^^^^^^^^^^^^^^^^^^^^^^^^^^^^^^^^^^^^^^^^^^^^
  File "/Users/angel/Desktop/Proyecto Grupo BIA/GrupoBIA/venvGrupoBIA/lib/python3.12/site-packages/django/db/models/query.py", line 818, in bulk_create
    returned_columns = self._batched_insert(
                       ^^^^^^^^^^^^^^^^^^^^^
  File "/Users/angel/Desktop/Proyecto Grupo BIA/GrupoBIA/venvGrupoBIA/lib/python3.12/site-packages/django/db/models/query.py", line 1875, in _batched_insert
    self._insert(
  File "/Users/angel/Desktop/Proyecto Grupo BIA/GrupoBIA/venvGrupoBIA/lib/python3.12/site-packages/django/db/models/query.py", line 1847, in _insert
    return query.get_compiler(using=using).execute_sql(returning_fields)
           ^^^^^^^^^^^^^^^^^^^^^^^^^^^^^^^^^^^^^^^^^^^^^^^^^^^^^^^^^^^^^
  File "/Users/angel/Desktop/Proyecto Grupo BIA/GrupoBIA/venvGrupoBIA/lib/python3.12/site-packages/django/db/models/sql/compiler.py", line 1836, in execute_sql
    cursor.execute(sql, params)
  File "/Users/angel/Desktop/Proyecto Grupo BIA/GrupoBIA/venvGrupoBIA/lib/python3.12/site-packages/django/db/backends/utils.py", line 122, in execute
    return super().execute(sql, params)
           ^^^^^^^^^^^^^^^^^^^^^^^^^^^^
  File "/Users/angel/Desktop/Proyecto Grupo BIA/GrupoBIA/venvGrupoBIA/lib/python3.12/site-packages/django/db/backends/utils.py", line 79, in execute
    return self._execute_with_wrappers(
           ^^^^^^^^^^^^^^^^^^^^^^^^^^^^
  File "/Users/angel/Desktop/Proyecto Grupo BIA/GrupoBIA/venvGrupoBIA/lib/python3.12/site-packages/django/db/backends/utils.py", line 92, in _execute_with_wrappers
    return executor(sql, params, many, context)
           ^^^^^^^^^^^^^^^^^^^^^^^^^^^^^^^^^^^^
  File "/Users/angel/Desktop/Proyecto Grupo BIA/GrupoBIA/venvGrupoBIA/lib/python3.12/site-packages/django/db/backends/utils.py", line 100, in _execute
    with self.db.wrap_database_errors:
         ^^^^^^^^^^^^^^^^^^^^^^^^^^^^
  File "/Users/angel/Desktop/Proyecto Grupo BIA/GrupoBIA/venvGrupoBIA/lib/python3.12/site-packages/django/db/utils.py", line 91, in __exit__
    raise dj_exc_value.with_traceback(traceback) from exc_value
  File "/Users/angel/Desktop/Proyecto Grupo BIA/GrupoBIA/venvGrupoBIA/lib/python3.12/site-packages/django/db/backends/utils.py", line 105, in _execute
    return self.cursor.execute(sql, params)
           ^^^^^^^^^^^^^^^^^^^^^^^^^^^^^^^^
django.db.utils.IntegrityError: duplicate key value violates unique constraint "db_bia_pkey"
DETAIL:  Key (id_pago_unico)=(211816) already exists.


[2025-08-06 13:47:48,653] ERROR django.request - Internal Server Error: /carga-datos/api/confirmar/
[2025-08-06 13:47:48,654] ERROR django.request - Internal Server Error: /carga-datos/api/confirmar/
[2025-08-06 13:52:13,548] WARNING django.request - Not Found: /api/certificado/generar/
[2025-08-06 14:00:07,313] WARNING django.request - Unauthorized: /api/token/
[2025-08-06 14:00:34,834] WARNING django.request - Not Found: /api/certificado/generar/
[2025-08-06 14:09:50,741] WARNING django.request - Unauthorized: /api/token/
[2025-08-06 14:10:39,999] WARNING django.request - Not Found: /main.e227e5d230e518355950.hot-update.json
[2025-08-06 14:11:38,997] WARNING django.request - Not Found: /main.69849ccee39926e8725a.hot-update.json
[2025-08-06 14:24:23,817] WARNING django.request - Not Found: /api/certificado/generar/
[2025-08-06 14:25:00,392] WARNING django.request - Unauthorized: /api/token/
[2025-08-06 14:32:12,077] WARNING django.request - Not Found: /main.869b8969a6f9d790fe9a.hot-update.json
[2025-08-06 14:46:57,127] WARNING django.request - Unauthorized: /api/token/
[2025-08-06 14:48:10,749] WARNING django.request - Unauthorized: /api/token/
[2025-08-06 14:59:20,370] WARNING django.request - Unauthorized: /api/token/
[2025-08-06 15:05:02,040] INFO django.request - [angel] Previsualización cargada de 'Base de Datos BIA.xlsx' con 14 registros.
[2025-08-06 15:05:02,698] ERROR django.request - Error en api_confirmar_carga:
Traceback (most recent call last):
  File "/Users/angel/Desktop/Proyecto Grupo BIA/GrupoBIA/venvGrupoBIA/lib/python3.12/site-packages/django/db/backends/utils.py", line 105, in _execute
    return self.cursor.execute(sql, params)
           ^^^^^^^^^^^^^^^^^^^^^^^^^^^^^^^^
psycopg2.errors.UniqueViolation: duplicate key value violates unique constraint "db_bia_pkey"
DETAIL:  Key (id_pago_unico)=(211816) already exists.


The above exception was the direct cause of the following exception:

Traceback (most recent call last):
  File "/Users/angel/Desktop/Proyecto Grupo BIA/GrupoBIA/proyecto_bia/proyecto_bia/carga_datos/views.py", line 213, in api_confirmar_carga
    BaseDeDatosBia.objects.bulk_create(registros, batch_size=100)
  File "/Users/angel/Desktop/Proyecto Grupo BIA/GrupoBIA/venvGrupoBIA/lib/python3.12/site-packages/django/db/models/manager.py", line 87, in manager_method
    return getattr(self.get_queryset(), name)(*args, **kwargs)
           ^^^^^^^^^^^^^^^^^^^^^^^^^^^^^^^^^^^^^^^^^^^^^^^^^^^
  File "/Users/angel/Desktop/Proyecto Grupo BIA/GrupoBIA/venvGrupoBIA/lib/python3.12/site-packages/django/db/models/query.py", line 818, in bulk_create
    returned_columns = self._batched_insert(
                       ^^^^^^^^^^^^^^^^^^^^^
  File "/Users/angel/Desktop/Proyecto Grupo BIA/GrupoBIA/venvGrupoBIA/lib/python3.12/site-packages/django/db/models/query.py", line 1875, in _batched_insert
    self._insert(
  File "/Users/angel/Desktop/Proyecto Grupo BIA/GrupoBIA/venvGrupoBIA/lib/python3.12/site-packages/django/db/models/query.py", line 1847, in _insert
    return query.get_compiler(using=using).execute_sql(returning_fields)
           ^^^^^^^^^^^^^^^^^^^^^^^^^^^^^^^^^^^^^^^^^^^^^^^^^^^^^^^^^^^^^
  File "/Users/angel/Desktop/Proyecto Grupo BIA/GrupoBIA/venvGrupoBIA/lib/python3.12/site-packages/django/db/models/sql/compiler.py", line 1836, in execute_sql
    cursor.execute(sql, params)
  File "/Users/angel/Desktop/Proyecto Grupo BIA/GrupoBIA/venvGrupoBIA/lib/python3.12/site-packages/django/db/backends/utils.py", line 122, in execute
    return super().execute(sql, params)
           ^^^^^^^^^^^^^^^^^^^^^^^^^^^^
  File "/Users/angel/Desktop/Proyecto Grupo BIA/GrupoBIA/venvGrupoBIA/lib/python3.12/site-packages/django/db/backends/utils.py", line 79, in execute
    return self._execute_with_wrappers(
           ^^^^^^^^^^^^^^^^^^^^^^^^^^^^
  File "/Users/angel/Desktop/Proyecto Grupo BIA/GrupoBIA/venvGrupoBIA/lib/python3.12/site-packages/django/db/backends/utils.py", line 92, in _execute_with_wrappers
    return executor(sql, params, many, context)
           ^^^^^^^^^^^^^^^^^^^^^^^^^^^^^^^^^^^^
  File "/Users/angel/Desktop/Proyecto Grupo BIA/GrupoBIA/venvGrupoBIA/lib/python3.12/site-packages/django/db/backends/utils.py", line 100, in _execute
    with self.db.wrap_database_errors:
         ^^^^^^^^^^^^^^^^^^^^^^^^^^^^
  File "/Users/angel/Desktop/Proyecto Grupo BIA/GrupoBIA/venvGrupoBIA/lib/python3.12/site-packages/django/db/utils.py", line 91, in __exit__
    raise dj_exc_value.with_traceback(traceback) from exc_value
  File "/Users/angel/Desktop/Proyecto Grupo BIA/GrupoBIA/venvGrupoBIA/lib/python3.12/site-packages/django/db/backends/utils.py", line 105, in _execute
    return self.cursor.execute(sql, params)
           ^^^^^^^^^^^^^^^^^^^^^^^^^^^^^^^^
django.db.utils.IntegrityError: duplicate key value violates unique constraint "db_bia_pkey"
DETAIL:  Key (id_pago_unico)=(211816) already exists.


[2025-08-06 15:05:02,699] ERROR django.request - Internal Server Error: /carga-datos/api/confirmar/
[2025-08-06 15:05:02,731] ERROR django.request - Error en api_confirmar_carga:
Traceback (most recent call last):
  File "/Users/angel/Desktop/Proyecto Grupo BIA/GrupoBIA/venvGrupoBIA/lib/python3.12/site-packages/django/db/backends/utils.py", line 105, in _execute
    return self.cursor.execute(sql, params)
           ^^^^^^^^^^^^^^^^^^^^^^^^^^^^^^^^
psycopg2.errors.UniqueViolation: duplicate key value violates unique constraint "db_bia_pkey"
DETAIL:  Key (id_pago_unico)=(211816) already exists.


The above exception was the direct cause of the following exception:

Traceback (most recent call last):
  File "/Users/angel/Desktop/Proyecto Grupo BIA/GrupoBIA/proyecto_bia/proyecto_bia/carga_datos/views.py", line 213, in api_confirmar_carga
    BaseDeDatosBia.objects.bulk_create(registros, batch_size=100)
  File "/Users/angel/Desktop/Proyecto Grupo BIA/GrupoBIA/venvGrupoBIA/lib/python3.12/site-packages/django/db/models/manager.py", line 87, in manager_method
    return getattr(self.get_queryset(), name)(*args, **kwargs)
           ^^^^^^^^^^^^^^^^^^^^^^^^^^^^^^^^^^^^^^^^^^^^^^^^^^^
  File "/Users/angel/Desktop/Proyecto Grupo BIA/GrupoBIA/venvGrupoBIA/lib/python3.12/site-packages/django/db/models/query.py", line 818, in bulk_create
    returned_columns = self._batched_insert(
                       ^^^^^^^^^^^^^^^^^^^^^
  File "/Users/angel/Desktop/Proyecto Grupo BIA/GrupoBIA/venvGrupoBIA/lib/python3.12/site-packages/django/db/models/query.py", line 1875, in _batched_insert
    self._insert(
  File "/Users/angel/Desktop/Proyecto Grupo BIA/GrupoBIA/venvGrupoBIA/lib/python3.12/site-packages/django/db/models/query.py", line 1847, in _insert
    return query.get_compiler(using=using).execute_sql(returning_fields)
           ^^^^^^^^^^^^^^^^^^^^^^^^^^^^^^^^^^^^^^^^^^^^^^^^^^^^^^^^^^^^^
  File "/Users/angel/Desktop/Proyecto Grupo BIA/GrupoBIA/venvGrupoBIA/lib/python3.12/site-packages/django/db/models/sql/compiler.py", line 1836, in execute_sql
    cursor.execute(sql, params)
  File "/Users/angel/Desktop/Proyecto Grupo BIA/GrupoBIA/venvGrupoBIA/lib/python3.12/site-packages/django/db/backends/utils.py", line 122, in execute
    return super().execute(sql, params)
           ^^^^^^^^^^^^^^^^^^^^^^^^^^^^
  File "/Users/angel/Desktop/Proyecto Grupo BIA/GrupoBIA/venvGrupoBIA/lib/python3.12/site-packages/django/db/backends/utils.py", line 79, in execute
    return self._execute_with_wrappers(
           ^^^^^^^^^^^^^^^^^^^^^^^^^^^^
  File "/Users/angel/Desktop/Proyecto Grupo BIA/GrupoBIA/venvGrupoBIA/lib/python3.12/site-packages/django/db/backends/utils.py", line 92, in _execute_with_wrappers
    return executor(sql, params, many, context)
           ^^^^^^^^^^^^^^^^^^^^^^^^^^^^^^^^^^^^
  File "/Users/angel/Desktop/Proyecto Grupo BIA/GrupoBIA/venvGrupoBIA/lib/python3.12/site-packages/django/db/backends/utils.py", line 100, in _execute
    with self.db.wrap_database_errors:
         ^^^^^^^^^^^^^^^^^^^^^^^^^^^^
  File "/Users/angel/Desktop/Proyecto Grupo BIA/GrupoBIA/venvGrupoBIA/lib/python3.12/site-packages/django/db/utils.py", line 91, in __exit__
    raise dj_exc_value.with_traceback(traceback) from exc_value
  File "/Users/angel/Desktop/Proyecto Grupo BIA/GrupoBIA/venvGrupoBIA/lib/python3.12/site-packages/django/db/backends/utils.py", line 105, in _execute
    return self.cursor.execute(sql, params)
           ^^^^^^^^^^^^^^^^^^^^^^^^^^^^^^^^
django.db.utils.IntegrityError: duplicate key value violates unique constraint "db_bia_pkey"
DETAIL:  Key (id_pago_unico)=(211816) already exists.


[2025-08-06 15:05:02,731] ERROR django.request - Internal Server Error: /carga-datos/api/confirmar/
[2025-08-06 15:08:33,163] WARNING django.request - Not Found: /api/certificado/generar/
[2025-08-06 15:09:52,016] WARNING django.request - Not Found: /api/certificado/generar/
[2025-08-06 15:31:34,604] INFO django.request - [angel] Previsualización cargada de 'Base de Datos BIA - Carga Test.xlsx' con 1 registros.
[2025-08-06 15:31:35,316] ERROR django.request - Error en api_confirmar_carga:
Traceback (most recent call last):
  File "/Users/angel/Desktop/Proyecto Grupo BIA/GrupoBIA/venvGrupoBIA/lib/python3.12/site-packages/django/db/backends/utils.py", line 105, in _execute
    return self.cursor.execute(sql, params)
           ^^^^^^^^^^^^^^^^^^^^^^^^^^^^^^^^
psycopg2.errors.UniqueViolation: duplicate key value violates unique constraint "db_bia_pkey"
DETAIL:  Key (id_pago_unico)=(211241) already exists.


The above exception was the direct cause of the following exception:

Traceback (most recent call last):
  File "/Users/angel/Desktop/Proyecto Grupo BIA/GrupoBIA/proyecto_bia/proyecto_bia/carga_datos/views.py", line 213, in api_confirmar_carga
    BaseDeDatosBia.objects.bulk_create(registros, batch_size=100)
  File "/Users/angel/Desktop/Proyecto Grupo BIA/GrupoBIA/venvGrupoBIA/lib/python3.12/site-packages/django/db/models/manager.py", line 87, in manager_method
    return getattr(self.get_queryset(), name)(*args, **kwargs)
           ^^^^^^^^^^^^^^^^^^^^^^^^^^^^^^^^^^^^^^^^^^^^^^^^^^^
  File "/Users/angel/Desktop/Proyecto Grupo BIA/GrupoBIA/venvGrupoBIA/lib/python3.12/site-packages/django/db/models/query.py", line 818, in bulk_create
    returned_columns = self._batched_insert(
                       ^^^^^^^^^^^^^^^^^^^^^
  File "/Users/angel/Desktop/Proyecto Grupo BIA/GrupoBIA/venvGrupoBIA/lib/python3.12/site-packages/django/db/models/query.py", line 1875, in _batched_insert
    self._insert(
  File "/Users/angel/Desktop/Proyecto Grupo BIA/GrupoBIA/venvGrupoBIA/lib/python3.12/site-packages/django/db/models/query.py", line 1847, in _insert
    return query.get_compiler(using=using).execute_sql(returning_fields)
           ^^^^^^^^^^^^^^^^^^^^^^^^^^^^^^^^^^^^^^^^^^^^^^^^^^^^^^^^^^^^^
  File "/Users/angel/Desktop/Proyecto Grupo BIA/GrupoBIA/venvGrupoBIA/lib/python3.12/site-packages/django/db/models/sql/compiler.py", line 1836, in execute_sql
    cursor.execute(sql, params)
  File "/Users/angel/Desktop/Proyecto Grupo BIA/GrupoBIA/venvGrupoBIA/lib/python3.12/site-packages/django/db/backends/utils.py", line 122, in execute
    return super().execute(sql, params)
           ^^^^^^^^^^^^^^^^^^^^^^^^^^^^
  File "/Users/angel/Desktop/Proyecto Grupo BIA/GrupoBIA/venvGrupoBIA/lib/python3.12/site-packages/django/db/backends/utils.py", line 79, in execute
    return self._execute_with_wrappers(
           ^^^^^^^^^^^^^^^^^^^^^^^^^^^^
  File "/Users/angel/Desktop/Proyecto Grupo BIA/GrupoBIA/venvGrupoBIA/lib/python3.12/site-packages/django/db/backends/utils.py", line 92, in _execute_with_wrappers
    return executor(sql, params, many, context)
           ^^^^^^^^^^^^^^^^^^^^^^^^^^^^^^^^^^^^
  File "/Users/angel/Desktop/Proyecto Grupo BIA/GrupoBIA/venvGrupoBIA/lib/python3.12/site-packages/django/db/backends/utils.py", line 100, in _execute
    with self.db.wrap_database_errors:
         ^^^^^^^^^^^^^^^^^^^^^^^^^^^^
  File "/Users/angel/Desktop/Proyecto Grupo BIA/GrupoBIA/venvGrupoBIA/lib/python3.12/site-packages/django/db/utils.py", line 91, in __exit__
    raise dj_exc_value.with_traceback(traceback) from exc_value
  File "/Users/angel/Desktop/Proyecto Grupo BIA/GrupoBIA/venvGrupoBIA/lib/python3.12/site-packages/django/db/backends/utils.py", line 105, in _execute
    return self.cursor.execute(sql, params)
           ^^^^^^^^^^^^^^^^^^^^^^^^^^^^^^^^
django.db.utils.IntegrityError: duplicate key value violates unique constraint "db_bia_pkey"
DETAIL:  Key (id_pago_unico)=(211241) already exists.


[2025-08-06 15:31:35,318] ERROR django.request - Internal Server Error: /carga-datos/api/confirmar/
[2025-08-06 15:31:37,646] WARNING django.request - Not Found: /carga-datos/api/errores/
[2025-08-06 15:31:38,018] WARNING django.request - Not Found: /carga-datos/api/errores/
[2025-08-06 15:32:51,244] ERROR django.request - Error en api_confirmar_carga:
Traceback (most recent call last):
  File "/Users/angel/Desktop/Proyecto Grupo BIA/GrupoBIA/venvGrupoBIA/lib/python3.12/site-packages/django/db/backends/utils.py", line 105, in _execute
    return self.cursor.execute(sql, params)
           ^^^^^^^^^^^^^^^^^^^^^^^^^^^^^^^^
psycopg2.errors.UniqueViolation: duplicate key value violates unique constraint "db_bia_pkey"
DETAIL:  Key (id_pago_unico)=(211241) already exists.


The above exception was the direct cause of the following exception:

Traceback (most recent call last):
  File "/Users/angel/Desktop/Proyecto Grupo BIA/GrupoBIA/proyecto_bia/proyecto_bia/carga_datos/views.py", line 213, in api_confirmar_carga
    BaseDeDatosBia.objects.bulk_create(registros, batch_size=100)
  File "/Users/angel/Desktop/Proyecto Grupo BIA/GrupoBIA/venvGrupoBIA/lib/python3.12/site-packages/django/db/models/manager.py", line 87, in manager_method
    return getattr(self.get_queryset(), name)(*args, **kwargs)
           ^^^^^^^^^^^^^^^^^^^^^^^^^^^^^^^^^^^^^^^^^^^^^^^^^^^
  File "/Users/angel/Desktop/Proyecto Grupo BIA/GrupoBIA/venvGrupoBIA/lib/python3.12/site-packages/django/db/models/query.py", line 818, in bulk_create
    returned_columns = self._batched_insert(
                       ^^^^^^^^^^^^^^^^^^^^^
  File "/Users/angel/Desktop/Proyecto Grupo BIA/GrupoBIA/venvGrupoBIA/lib/python3.12/site-packages/django/db/models/query.py", line 1875, in _batched_insert
    self._insert(
  File "/Users/angel/Desktop/Proyecto Grupo BIA/GrupoBIA/venvGrupoBIA/lib/python3.12/site-packages/django/db/models/query.py", line 1847, in _insert
    return query.get_compiler(using=using).execute_sql(returning_fields)
           ^^^^^^^^^^^^^^^^^^^^^^^^^^^^^^^^^^^^^^^^^^^^^^^^^^^^^^^^^^^^^
  File "/Users/angel/Desktop/Proyecto Grupo BIA/GrupoBIA/venvGrupoBIA/lib/python3.12/site-packages/django/db/models/sql/compiler.py", line 1836, in execute_sql
    cursor.execute(sql, params)
  File "/Users/angel/Desktop/Proyecto Grupo BIA/GrupoBIA/venvGrupoBIA/lib/python3.12/site-packages/django/db/backends/utils.py", line 122, in execute
    return super().execute(sql, params)
           ^^^^^^^^^^^^^^^^^^^^^^^^^^^^
  File "/Users/angel/Desktop/Proyecto Grupo BIA/GrupoBIA/venvGrupoBIA/lib/python3.12/site-packages/django/db/backends/utils.py", line 79, in execute
    return self._execute_with_wrappers(
           ^^^^^^^^^^^^^^^^^^^^^^^^^^^^
  File "/Users/angel/Desktop/Proyecto Grupo BIA/GrupoBIA/venvGrupoBIA/lib/python3.12/site-packages/django/db/backends/utils.py", line 92, in _execute_with_wrappers
    return executor(sql, params, many, context)
           ^^^^^^^^^^^^^^^^^^^^^^^^^^^^^^^^^^^^
  File "/Users/angel/Desktop/Proyecto Grupo BIA/GrupoBIA/venvGrupoBIA/lib/python3.12/site-packages/django/db/backends/utils.py", line 100, in _execute
    with self.db.wrap_database_errors:
         ^^^^^^^^^^^^^^^^^^^^^^^^^^^^
  File "/Users/angel/Desktop/Proyecto Grupo BIA/GrupoBIA/venvGrupoBIA/lib/python3.12/site-packages/django/db/utils.py", line 91, in __exit__
    raise dj_exc_value.with_traceback(traceback) from exc_value
  File "/Users/angel/Desktop/Proyecto Grupo BIA/GrupoBIA/venvGrupoBIA/lib/python3.12/site-packages/django/db/backends/utils.py", line 105, in _execute
    return self.cursor.execute(sql, params)
           ^^^^^^^^^^^^^^^^^^^^^^^^^^^^^^^^
django.db.utils.IntegrityError: duplicate key value violates unique constraint "db_bia_pkey"
DETAIL:  Key (id_pago_unico)=(211241) already exists.


[2025-08-06 15:32:51,245] ERROR django.request - Error en api_confirmar_carga:
Traceback (most recent call last):
  File "/Users/angel/Desktop/Proyecto Grupo BIA/GrupoBIA/venvGrupoBIA/lib/python3.12/site-packages/django/db/backends/utils.py", line 105, in _execute
    return self.cursor.execute(sql, params)
           ^^^^^^^^^^^^^^^^^^^^^^^^^^^^^^^^
psycopg2.errors.UniqueViolation: duplicate key value violates unique constraint "db_bia_pkey"
DETAIL:  Key (id_pago_unico)=(211241) already exists.


The above exception was the direct cause of the following exception:

Traceback (most recent call last):
  File "/Users/angel/Desktop/Proyecto Grupo BIA/GrupoBIA/proyecto_bia/proyecto_bia/carga_datos/views.py", line 213, in api_confirmar_carga
    BaseDeDatosBia.objects.bulk_create(registros, batch_size=100)
  File "/Users/angel/Desktop/Proyecto Grupo BIA/GrupoBIA/venvGrupoBIA/lib/python3.12/site-packages/django/db/models/manager.py", line 87, in manager_method
    return getattr(self.get_queryset(), name)(*args, **kwargs)
           ^^^^^^^^^^^^^^^^^^^^^^^^^^^^^^^^^^^^^^^^^^^^^^^^^^^
  File "/Users/angel/Desktop/Proyecto Grupo BIA/GrupoBIA/venvGrupoBIA/lib/python3.12/site-packages/django/db/models/query.py", line 818, in bulk_create
    returned_columns = self._batched_insert(
                       ^^^^^^^^^^^^^^^^^^^^^
  File "/Users/angel/Desktop/Proyecto Grupo BIA/GrupoBIA/venvGrupoBIA/lib/python3.12/site-packages/django/db/models/query.py", line 1875, in _batched_insert
    self._insert(
  File "/Users/angel/Desktop/Proyecto Grupo BIA/GrupoBIA/venvGrupoBIA/lib/python3.12/site-packages/django/db/models/query.py", line 1847, in _insert
    return query.get_compiler(using=using).execute_sql(returning_fields)
           ^^^^^^^^^^^^^^^^^^^^^^^^^^^^^^^^^^^^^^^^^^^^^^^^^^^^^^^^^^^^^
  File "/Users/angel/Desktop/Proyecto Grupo BIA/GrupoBIA/venvGrupoBIA/lib/python3.12/site-packages/django/db/models/sql/compiler.py", line 1836, in execute_sql
    cursor.execute(sql, params)
  File "/Users/angel/Desktop/Proyecto Grupo BIA/GrupoBIA/venvGrupoBIA/lib/python3.12/site-packages/django/db/backends/utils.py", line 122, in execute
    return super().execute(sql, params)
           ^^^^^^^^^^^^^^^^^^^^^^^^^^^^
  File "/Users/angel/Desktop/Proyecto Grupo BIA/GrupoBIA/venvGrupoBIA/lib/python3.12/site-packages/django/db/backends/utils.py", line 79, in execute
    return self._execute_with_wrappers(
           ^^^^^^^^^^^^^^^^^^^^^^^^^^^^
  File "/Users/angel/Desktop/Proyecto Grupo BIA/GrupoBIA/venvGrupoBIA/lib/python3.12/site-packages/django/db/backends/utils.py", line 92, in _execute_with_wrappers
    return executor(sql, params, many, context)
           ^^^^^^^^^^^^^^^^^^^^^^^^^^^^^^^^^^^^
  File "/Users/angel/Desktop/Proyecto Grupo BIA/GrupoBIA/venvGrupoBIA/lib/python3.12/site-packages/django/db/backends/utils.py", line 100, in _execute
    with self.db.wrap_database_errors:
         ^^^^^^^^^^^^^^^^^^^^^^^^^^^^
  File "/Users/angel/Desktop/Proyecto Grupo BIA/GrupoBIA/venvGrupoBIA/lib/python3.12/site-packages/django/db/utils.py", line 91, in __exit__
    raise dj_exc_value.with_traceback(traceback) from exc_value
  File "/Users/angel/Desktop/Proyecto Grupo BIA/GrupoBIA/venvGrupoBIA/lib/python3.12/site-packages/django/db/backends/utils.py", line 105, in _execute
    return self.cursor.execute(sql, params)
           ^^^^^^^^^^^^^^^^^^^^^^^^^^^^^^^^
django.db.utils.IntegrityError: duplicate key value violates unique constraint "db_bia_pkey"
DETAIL:  Key (id_pago_unico)=(211241) already exists.


[2025-08-06 15:32:51,247] ERROR django.request - Internal Server Error: /carga-datos/api/confirmar/
[2025-08-06 15:32:51,247] ERROR django.request - Internal Server Error: /carga-datos/api/confirmar/
[2025-08-06 15:33:18,028] WARNING django.request - Not Found: /api/certificado/generar/
[2025-08-06 15:34:18,292] INFO django.request - [angel] Previsualización cargada de 'Base de Datos BIA - Carga Test.xlsx' con 1 registros.
[2025-08-06 15:34:19,004] ERROR django.request - Error en api_confirmar_carga:
Traceback (most recent call last):
  File "/Users/angel/Desktop/Proyecto Grupo BIA/GrupoBIA/venvGrupoBIA/lib/python3.12/site-packages/django/db/backends/utils.py", line 105, in _execute
    return self.cursor.execute(sql, params)
           ^^^^^^^^^^^^^^^^^^^^^^^^^^^^^^^^
psycopg2.errors.UniqueViolation: duplicate key value violates unique constraint "db_bia_pkey"
DETAIL:  Key (id_pago_unico)=(211241) already exists.


The above exception was the direct cause of the following exception:

Traceback (most recent call last):
  File "/Users/angel/Desktop/Proyecto Grupo BIA/GrupoBIA/proyecto_bia/proyecto_bia/carga_datos/views.py", line 213, in api_confirmar_carga
    BaseDeDatosBia.objects.bulk_create(registros, batch_size=100)
  File "/Users/angel/Desktop/Proyecto Grupo BIA/GrupoBIA/venvGrupoBIA/lib/python3.12/site-packages/django/db/models/manager.py", line 87, in manager_method
    return getattr(self.get_queryset(), name)(*args, **kwargs)
           ^^^^^^^^^^^^^^^^^^^^^^^^^^^^^^^^^^^^^^^^^^^^^^^^^^^
  File "/Users/angel/Desktop/Proyecto Grupo BIA/GrupoBIA/venvGrupoBIA/lib/python3.12/site-packages/django/db/models/query.py", line 818, in bulk_create
    returned_columns = self._batched_insert(
                       ^^^^^^^^^^^^^^^^^^^^^
  File "/Users/angel/Desktop/Proyecto Grupo BIA/GrupoBIA/venvGrupoBIA/lib/python3.12/site-packages/django/db/models/query.py", line 1875, in _batched_insert
    self._insert(
  File "/Users/angel/Desktop/Proyecto Grupo BIA/GrupoBIA/venvGrupoBIA/lib/python3.12/site-packages/django/db/models/query.py", line 1847, in _insert
    return query.get_compiler(using=using).execute_sql(returning_fields)
           ^^^^^^^^^^^^^^^^^^^^^^^^^^^^^^^^^^^^^^^^^^^^^^^^^^^^^^^^^^^^^
  File "/Users/angel/Desktop/Proyecto Grupo BIA/GrupoBIA/venvGrupoBIA/lib/python3.12/site-packages/django/db/models/sql/compiler.py", line 1836, in execute_sql
    cursor.execute(sql, params)
  File "/Users/angel/Desktop/Proyecto Grupo BIA/GrupoBIA/venvGrupoBIA/lib/python3.12/site-packages/django/db/backends/utils.py", line 122, in execute
    return super().execute(sql, params)
           ^^^^^^^^^^^^^^^^^^^^^^^^^^^^
  File "/Users/angel/Desktop/Proyecto Grupo BIA/GrupoBIA/venvGrupoBIA/lib/python3.12/site-packages/django/db/backends/utils.py", line 79, in execute
    return self._execute_with_wrappers(
           ^^^^^^^^^^^^^^^^^^^^^^^^^^^^
  File "/Users/angel/Desktop/Proyecto Grupo BIA/GrupoBIA/venvGrupoBIA/lib/python3.12/site-packages/django/db/backends/utils.py", line 92, in _execute_with_wrappers
    return executor(sql, params, many, context)
           ^^^^^^^^^^^^^^^^^^^^^^^^^^^^^^^^^^^^
  File "/Users/angel/Desktop/Proyecto Grupo BIA/GrupoBIA/venvGrupoBIA/lib/python3.12/site-packages/django/db/backends/utils.py", line 100, in _execute
    with self.db.wrap_database_errors:
         ^^^^^^^^^^^^^^^^^^^^^^^^^^^^
  File "/Users/angel/Desktop/Proyecto Grupo BIA/GrupoBIA/venvGrupoBIA/lib/python3.12/site-packages/django/db/utils.py", line 91, in __exit__
    raise dj_exc_value.with_traceback(traceback) from exc_value
  File "/Users/angel/Desktop/Proyecto Grupo BIA/GrupoBIA/venvGrupoBIA/lib/python3.12/site-packages/django/db/backends/utils.py", line 105, in _execute
    return self.cursor.execute(sql, params)
           ^^^^^^^^^^^^^^^^^^^^^^^^^^^^^^^^
django.db.utils.IntegrityError: duplicate key value violates unique constraint "db_bia_pkey"
DETAIL:  Key (id_pago_unico)=(211241) already exists.


[2025-08-06 15:34:19,004] ERROR django.request - Internal Server Error: /carga-datos/api/confirmar/
[2025-08-06 15:34:21,368] WARNING django.request - Not Found: /carga-datos/api/errores/
[2025-08-06 15:34:21,711] WARNING django.request - Not Found: /carga-datos/api/errores/
[2025-08-06 15:35:26,226] INFO django.request - [angel] Previsualización cargada de 'Base de Datos BIA - Carga Test.xlsx' con 1 registros.
[2025-08-06 15:35:26,901] ERROR django.request - Error en api_confirmar_carga:
Traceback (most recent call last):
  File "/Users/angel/Desktop/Proyecto Grupo BIA/GrupoBIA/venvGrupoBIA/lib/python3.12/site-packages/django/db/backends/utils.py", line 105, in _execute
    return self.cursor.execute(sql, params)
           ^^^^^^^^^^^^^^^^^^^^^^^^^^^^^^^^
psycopg2.errors.UniqueViolation: duplicate key value violates unique constraint "db_bia_pkey"
DETAIL:  Key (id_pago_unico)=(211241) already exists.


The above exception was the direct cause of the following exception:

Traceback (most recent call last):
  File "/Users/angel/Desktop/Proyecto Grupo BIA/GrupoBIA/proyecto_bia/proyecto_bia/carga_datos/views.py", line 213, in api_confirmar_carga
    BaseDeDatosBia.objects.bulk_create(registros, batch_size=100)
  File "/Users/angel/Desktop/Proyecto Grupo BIA/GrupoBIA/venvGrupoBIA/lib/python3.12/site-packages/django/db/models/manager.py", line 87, in manager_method
    return getattr(self.get_queryset(), name)(*args, **kwargs)
           ^^^^^^^^^^^^^^^^^^^^^^^^^^^^^^^^^^^^^^^^^^^^^^^^^^^
  File "/Users/angel/Desktop/Proyecto Grupo BIA/GrupoBIA/venvGrupoBIA/lib/python3.12/site-packages/django/db/models/query.py", line 818, in bulk_create
    returned_columns = self._batched_insert(
                       ^^^^^^^^^^^^^^^^^^^^^
  File "/Users/angel/Desktop/Proyecto Grupo BIA/GrupoBIA/venvGrupoBIA/lib/python3.12/site-packages/django/db/models/query.py", line 1875, in _batched_insert
    self._insert(
  File "/Users/angel/Desktop/Proyecto Grupo BIA/GrupoBIA/venvGrupoBIA/lib/python3.12/site-packages/django/db/models/query.py", line 1847, in _insert
    return query.get_compiler(using=using).execute_sql(returning_fields)
           ^^^^^^^^^^^^^^^^^^^^^^^^^^^^^^^^^^^^^^^^^^^^^^^^^^^^^^^^^^^^^
  File "/Users/angel/Desktop/Proyecto Grupo BIA/GrupoBIA/venvGrupoBIA/lib/python3.12/site-packages/django/db/models/sql/compiler.py", line 1836, in execute_sql
    cursor.execute(sql, params)
  File "/Users/angel/Desktop/Proyecto Grupo BIA/GrupoBIA/venvGrupoBIA/lib/python3.12/site-packages/django/db/backends/utils.py", line 122, in execute
    return super().execute(sql, params)
           ^^^^^^^^^^^^^^^^^^^^^^^^^^^^
  File "/Users/angel/Desktop/Proyecto Grupo BIA/GrupoBIA/venvGrupoBIA/lib/python3.12/site-packages/django/db/backends/utils.py", line 79, in execute
    return self._execute_with_wrappers(
           ^^^^^^^^^^^^^^^^^^^^^^^^^^^^
  File "/Users/angel/Desktop/Proyecto Grupo BIA/GrupoBIA/venvGrupoBIA/lib/python3.12/site-packages/django/db/backends/utils.py", line 92, in _execute_with_wrappers
    return executor(sql, params, many, context)
           ^^^^^^^^^^^^^^^^^^^^^^^^^^^^^^^^^^^^
  File "/Users/angel/Desktop/Proyecto Grupo BIA/GrupoBIA/venvGrupoBIA/lib/python3.12/site-packages/django/db/backends/utils.py", line 100, in _execute
    with self.db.wrap_database_errors:
         ^^^^^^^^^^^^^^^^^^^^^^^^^^^^
  File "/Users/angel/Desktop/Proyecto Grupo BIA/GrupoBIA/venvGrupoBIA/lib/python3.12/site-packages/django/db/utils.py", line 91, in __exit__
    raise dj_exc_value.with_traceback(traceback) from exc_value
  File "/Users/angel/Desktop/Proyecto Grupo BIA/GrupoBIA/venvGrupoBIA/lib/python3.12/site-packages/django/db/backends/utils.py", line 105, in _execute
    return self.cursor.execute(sql, params)
           ^^^^^^^^^^^^^^^^^^^^^^^^^^^^^^^^
django.db.utils.IntegrityError: duplicate key value violates unique constraint "db_bia_pkey"
DETAIL:  Key (id_pago_unico)=(211241) already exists.


[2025-08-06 15:35:26,901] ERROR django.request - Error en api_confirmar_carga:
Traceback (most recent call last):
  File "/Users/angel/Desktop/Proyecto Grupo BIA/GrupoBIA/venvGrupoBIA/lib/python3.12/site-packages/django/db/backends/utils.py", line 105, in _execute
    return self.cursor.execute(sql, params)
           ^^^^^^^^^^^^^^^^^^^^^^^^^^^^^^^^
psycopg2.errors.UniqueViolation: duplicate key value violates unique constraint "db_bia_pkey"
DETAIL:  Key (id_pago_unico)=(211241) already exists.


The above exception was the direct cause of the following exception:

Traceback (most recent call last):
  File "/Users/angel/Desktop/Proyecto Grupo BIA/GrupoBIA/proyecto_bia/proyecto_bia/carga_datos/views.py", line 213, in api_confirmar_carga
    BaseDeDatosBia.objects.bulk_create(registros, batch_size=100)
  File "/Users/angel/Desktop/Proyecto Grupo BIA/GrupoBIA/venvGrupoBIA/lib/python3.12/site-packages/django/db/models/manager.py", line 87, in manager_method
    return getattr(self.get_queryset(), name)(*args, **kwargs)
           ^^^^^^^^^^^^^^^^^^^^^^^^^^^^^^^^^^^^^^^^^^^^^^^^^^^
  File "/Users/angel/Desktop/Proyecto Grupo BIA/GrupoBIA/venvGrupoBIA/lib/python3.12/site-packages/django/db/models/query.py", line 818, in bulk_create
    returned_columns = self._batched_insert(
                       ^^^^^^^^^^^^^^^^^^^^^
  File "/Users/angel/Desktop/Proyecto Grupo BIA/GrupoBIA/venvGrupoBIA/lib/python3.12/site-packages/django/db/models/query.py", line 1875, in _batched_insert
    self._insert(
  File "/Users/angel/Desktop/Proyecto Grupo BIA/GrupoBIA/venvGrupoBIA/lib/python3.12/site-packages/django/db/models/query.py", line 1847, in _insert
    return query.get_compiler(using=using).execute_sql(returning_fields)
           ^^^^^^^^^^^^^^^^^^^^^^^^^^^^^^^^^^^^^^^^^^^^^^^^^^^^^^^^^^^^^
  File "/Users/angel/Desktop/Proyecto Grupo BIA/GrupoBIA/venvGrupoBIA/lib/python3.12/site-packages/django/db/models/sql/compiler.py", line 1836, in execute_sql
    cursor.execute(sql, params)
  File "/Users/angel/Desktop/Proyecto Grupo BIA/GrupoBIA/venvGrupoBIA/lib/python3.12/site-packages/django/db/backends/utils.py", line 122, in execute
    return super().execute(sql, params)
           ^^^^^^^^^^^^^^^^^^^^^^^^^^^^
  File "/Users/angel/Desktop/Proyecto Grupo BIA/GrupoBIA/venvGrupoBIA/lib/python3.12/site-packages/django/db/backends/utils.py", line 79, in execute
    return self._execute_with_wrappers(
           ^^^^^^^^^^^^^^^^^^^^^^^^^^^^
  File "/Users/angel/Desktop/Proyecto Grupo BIA/GrupoBIA/venvGrupoBIA/lib/python3.12/site-packages/django/db/backends/utils.py", line 92, in _execute_with_wrappers
    return executor(sql, params, many, context)
           ^^^^^^^^^^^^^^^^^^^^^^^^^^^^^^^^^^^^
  File "/Users/angel/Desktop/Proyecto Grupo BIA/GrupoBIA/venvGrupoBIA/lib/python3.12/site-packages/django/db/backends/utils.py", line 100, in _execute
    with self.db.wrap_database_errors:
         ^^^^^^^^^^^^^^^^^^^^^^^^^^^^
  File "/Users/angel/Desktop/Proyecto Grupo BIA/GrupoBIA/venvGrupoBIA/lib/python3.12/site-packages/django/db/utils.py", line 91, in __exit__
    raise dj_exc_value.with_traceback(traceback) from exc_value
  File "/Users/angel/Desktop/Proyecto Grupo BIA/GrupoBIA/venvGrupoBIA/lib/python3.12/site-packages/django/db/backends/utils.py", line 105, in _execute
    return self.cursor.execute(sql, params)
           ^^^^^^^^^^^^^^^^^^^^^^^^^^^^^^^^
django.db.utils.IntegrityError: duplicate key value violates unique constraint "db_bia_pkey"
DETAIL:  Key (id_pago_unico)=(211241) already exists.


[2025-08-06 15:35:26,902] ERROR django.request - Internal Server Error: /carga-datos/api/confirmar/
[2025-08-06 15:35:26,902] ERROR django.request - Internal Server Error: /carga-datos/api/confirmar/
[2025-08-06 15:36:33,154] WARNING django.request - Not Found: /api/certificado/generar/
[2025-08-06 15:37:29,432] WARNING django.request - Not Found: /api/certificado/generar/
[2025-08-06 15:52:01,177] WARNING django.request - Not Found: /api/certificado/generar/
[2025-08-06 16:01:29,884] WARNING django.request - Not Found: /api/certificado/generar/
[2025-08-06 16:17:29,213] WARNING django.request - Not Found: /main.fa734fa8d180142971ee.hot-update.json
[2025-08-06 17:00:44,382] WARNING django.request - Not Found: /api/certificado/generar/
[2025-08-06 17:01:52,402] WARNING django.request - Not Found: /api/certificado/generar/
[2025-08-06 17:10:46,409] WARNING django.request - Unauthorized: /api/token/
[2025-08-06 18:21:21,450] WARNING django.request - Not Found: /main.7c4fcaf64985b99b793e.hot-update.json
[2025-08-06 19:51:24,517] WARNING django.request - Not Found: /api/mostrar-datos-bia/
[2025-08-06 20:01:19,140] WARNING django.request - Not Found: /api/mostrar-datos-bia/
[2025-08-06 20:01:41,760] WARNING django.request - Not Found: /api/mostrar-datos-bia/
[2025-08-06 20:04:55,429] WARNING django.request - Not Found: /proyecto_bia/frontend/src/images/LogoBIA.png
[2025-08-06 20:04:56,091] WARNING django.request - Not Found: /datos/proyecto_bia/frontend/src/images/LogoBIA.png
[2025-08-06 20:05:07,840] WARNING django.request - Not Found: /main.5bf135aa41270f1a8e23.hot-update.json
[2025-08-06 20:05:07,942] WARNING django.request - Not Found: /proyecto_bia/frontend/src/images/LogoBIA.png
[2025-08-06 20:05:07,969] WARNING django.request - Not Found: /proyecto_bia/frontend/src/images/LogoBIA.png
[2025-08-06 20:05:41,731] WARNING django.request - Not Found: /proyecto_bia/frontend/src/images/LogoBIA.png
[2025-08-06 20:05:42,091] WARNING django.request - Not Found: /proyecto_bia/frontend/src/images/LogoBIA.png
[2025-08-06 20:05:42,688] WARNING django.request - Not Found: /proyecto_bia/frontend/src/images/LogoBIA.png
[2025-08-06 20:05:55,175] WARNING django.request - Not Found: /proyecto_bia/frontend/src/images/LogoBIA.png
[2025-08-06 20:05:57,296] WARNING django.request - Not Found: /proyecto_bia/frontend/src/images/LogoBIA.png
[2025-08-06 20:05:58,853] WARNING django.request - Not Found: /proyecto_bia/frontend/src/images/LogoBIA.png
[2025-08-06 20:05:59,607] WARNING django.request - Not Found: /proyecto_bia/frontend/src/images/LogoBIA.png
[2025-08-06 20:06:00,993] WARNING django.request - Not Found: /proyecto_bia/frontend/src/images/LogoBIA.png
[2025-08-06 20:06:18,738] WARNING django.request - Not Found: /proyecto_bia/frontend/src/images/LogoBIA.png
[2025-08-06 20:06:49,650] WARNING django.request - Not Found: /proyecto_bia/frontend/src/images/LogoBIA.png
[2025-08-06 20:06:50,138] WARNING django.request - Not Found: /proyecto_bia/frontend/src/images/LogoBIA.png
[2025-08-06 20:06:50,578] WARNING django.request - Not Found: /proyecto_bia/frontend/src/images/LogoBIA.png
[2025-08-06 20:06:50,823] WARNING django.request - Not Found: /proyecto_bia/frontend/src/images/LogoBIA.png
[2025-08-06 20:06:51,054] WARNING django.request - Not Found: /proyecto_bia/frontend/src/images/LogoBIA.png
[2025-08-06 20:07:07,970] WARNING django.request - Not Found: /proyecto_bia/frontend/src/images/LogoBIA.png
[2025-08-06 20:07:28,082] WARNING django.request - Not Found: /proyecto_bia/frontend/src/images/LogoBIA.png
[2025-08-06 20:07:28,086] WARNING django.request - Not Found: /proyecto_bia/frontend/src/images/LogoBIA.png
[2025-08-06 20:07:37,300] WARNING django.request - Not Found: /proyecto_bia/frontend/src/images/LogoBIA.png
[2025-08-06 20:07:38,025] WARNING django.request - Not Found: /proyecto_bia/frontend/src/images/LogoBIA.png
[2025-08-06 20:07:38,772] WARNING django.request - Not Found: /proyecto_bia/frontend/src/images/LogoBIA.png
[2025-08-06 20:07:39,018] WARNING django.request - Not Found: /proyecto_bia/frontend/src/images/LogoBIA.png
[2025-08-06 20:07:44,060] WARNING django.request - Not Found: /proyecto_bia/frontend/src/images/LogoBIA.png
[2025-08-06 20:07:44,078] WARNING django.request - Not Found: /proyecto_bia/frontend/src/images/LogoBIA.png
[2025-08-06 20:07:47,418] WARNING django.request - Not Found: /proyecto_bia/frontend/src/images/LogoBIA.png
[2025-08-06 20:07:50,475] WARNING django.request - Not Found: /proyecto_bia/frontend/src/images/LogoBIA.png
[2025-08-06 20:07:56,516] WARNING django.request - Not Found: /carga-datos/proyecto_bia/frontend/src/images/LogoBIA.png
[2025-08-06 20:07:58,995] WARNING django.request - Not Found: /datos/proyecto_bia/frontend/src/images/LogoBIA.png
[2025-08-06 20:08:20,102] WARNING django.request - Not Found: /datos/proyecto_bia/frontend/src/images/LogoBIA.png
[2025-08-06 20:10:09,814] WARNING django.request - Not Found: /main.05d45fdc705d3ea3384a.hot-update.json
[2025-08-06 20:10:09,923] WARNING django.request - Not Found: /proyecto_bia/frontend/src/images/LogoBIA.png
[2025-08-06 20:10:10,018] WARNING django.request - Not Found: /datos/proyecto_bia/frontend/src/images/LogoBIA.png
[2025-08-06 20:10:11,081] WARNING django.request - Not Found: /main.05d45fdc705d3ea3384a.hot-update.json
[2025-08-06 20:10:11,263] WARNING django.request - Not Found: /proyecto_bia/frontend/src/images/LogoBIA.png
[2025-08-06 20:10:13,284] WARNING django.request - Not Found: /proyecto_bia/frontend/src/images/LogoBIA.png
[2025-08-06 20:10:23,805] WARNING django.request - Not Found: /proyecto_bia/frontend/src/images/LogoBIA.png
[2025-08-06 20:10:28,525] WARNING django.request - Not Found: /proyecto_bia/frontend/src/images/LogoBIA.png
[2025-08-06 20:10:31,208] WARNING django.request - Not Found: /proyecto_bia/frontend/src/images/LogoBIA.png
[2025-08-06 20:10:32,617] WARNING django.request - Not Found: /proyecto_bia/frontend/src/images/LogoBIA.png
[2025-08-06 20:10:34,204] WARNING django.request - Not Found: /proyecto_bia/frontend/src/images/LogoBIA.png
[2025-08-06 20:10:39,392] WARNING django.request - Not Found: /carga-datos/proyecto_bia/frontend/src/images/LogoBIA.png
[2025-08-06 20:10:43,734] WARNING django.request - Not Found: /datos/proyecto_bia/frontend/src/images/LogoBIA.png
[2025-08-06 20:11:17,216] WARNING django.request - Not Found: /api/mostrar-datos-bia/
[2025-08-06 20:11:26,255] WARNING django.request - Not Found: /proyecto_bia/frontend/src/images/LogoBIA.png
[2025-08-06 20:11:27,881] WARNING django.request - Not Found: /proyecto_bia/frontend/src/images/LogoBIA.png
[2025-08-06 20:11:30,609] WARNING django.request - Not Found: /proyecto_bia/frontend/src/images/LogoBIA.png
[2025-08-06 20:11:31,202] WARNING django.request - Not Found: /proyecto_bia/frontend/src/images/LogoBIA.png
[2025-08-06 20:11:31,898] WARNING django.request - Not Found: /proyecto_bia/frontend/src/images/LogoBIA.png
[2025-08-06 20:11:33,143] WARNING django.request - Not Found: /proyecto_bia/frontend/src/images/LogoBIA.png
[2025-08-06 20:11:49,533] WARNING django.request - Not Found: /proyecto_bia/frontend/src/images/LogoBIA.png
[2025-08-06 20:12:14,064] WARNING django.request - Not Found: /proyecto_bia/frontend/src/images/LogoBIA.png
[2025-08-06 20:12:18,334] WARNING django.request - Not Found: /proyecto_bia/frontend/src/images/LogoBIA.png
[2025-08-06 20:12:20,623] WARNING django.request - Not Found: /proyecto_bia/frontend/src/images/LogoBIA.png
[2025-08-06 20:12:26,763] WARNING django.request - Not Found: /carga-datos/proyecto_bia/frontend/src/images/LogoBIA.png
[2025-08-06 20:12:30,387] WARNING django.request - Not Found: /datos/proyecto_bia/frontend/src/images/LogoBIA.png
[2025-08-06 20:12:33,062] WARNING django.request - Not Found: /proyecto_bia/frontend/src/images/LogoBIA.png
[2025-08-06 20:12:36,166] WARNING django.request - Not Found: /datos/proyecto_bia/frontend/src/images/LogoBIA.png
[2025-08-06 20:12:40,879] WARNING django.request - Not Found: /carga-datos/proyecto_bia/frontend/src/images/LogoBIA.png
[2025-08-06 20:12:42,980] WARNING django.request - Not Found: /proyecto_bia/frontend/src/images/LogoBIA.png
[2025-08-06 20:12:43,679] WARNING django.request - Not Found: /proyecto_bia/frontend/src/images/LogoBIA.png
[2025-08-07 08:39:59,018] WARNING django.request - Not Found: /proyecto_bia/frontend/src/images/LogoBIA.png
[2025-08-07 08:40:00,300] WARNING django.request - Not Found: /main.a3b6a997568d4441796a.hot-update.json
[2025-08-07 08:40:00,925] WARNING django.request - Not Found: /proyecto_bia/frontend/src/images/LogoBIA.png
[2025-08-07 08:40:15,949] WARNING django.request - Not Found: /proyecto_bia/frontend/src/images/LogoBIA.png
[2025-08-07 08:40:22,623] WARNING django.request - Not Found: /proyecto_bia/frontend/src/images/LogoBIA.png
[2025-08-07 08:40:24,676] WARNING django.request - Not Found: /proyecto_bia/frontend/src/images/LogoBIA.png
[2025-08-07 08:40:26,010] WARNING django.request - Not Found: /proyecto_bia/frontend/src/images/LogoBIA.png
[2025-08-07 08:40:31,508] WARNING django.request - Not Found: /proyecto_bia/frontend/src/images/LogoBIA.png
[2025-08-07 08:40:32,757] WARNING django.request - Not Found: /proyecto_bia/frontend/src/images/LogoBIA.png
[2025-08-07 08:40:36,577] WARNING django.request - Not Found: /proyecto_bia/frontend/src/images/LogoBIA.png
[2025-08-07 08:40:43,794] WARNING django.request - Not Found: /proyecto_bia/frontend/src/images/LogoBIA.png
[2025-08-07 08:40:51,014] WARNING django.request - Not Found: /proyecto_bia/frontend/src/images/LogoBIA.png
[2025-08-07 08:40:59,761] WARNING django.request - Not Found: /proyecto_bia/frontend/src/images/LogoBIA.png
[2025-08-07 08:41:01,646] WARNING django.request - Not Found: /proyecto_bia/frontend/src/images/LogoBIA.png
[2025-08-07 08:41:02,731] WARNING django.request - Not Found: /proyecto_bia/frontend/src/images/LogoBIA.png
[2025-08-07 08:41:33,797] WARNING django.request - Not Found: /proyecto_bia/frontend/src/images/LogoBIA.png
[2025-08-07 09:39:40,442] WARNING django.request - Not Found: /proyecto_bia/frontend/src/images/LogoBIA.png
[2025-08-08 00:18:10,937] WARNING django.request - Not Found: /proyecto_bia/frontend/src/images/LogoBIA.png
[2025-08-08 00:18:16,414] WARNING django.request - Not Found: /proyecto_bia/frontend/src/images/LogoBIA.png
[2025-08-08 00:21:13,970] WARNING django.request - Not Found: /carga-datos/proyecto_bia/frontend/src/images/LogoBIA.png
[2025-08-08 00:21:19,311] WARNING django.request - Not Found: /datos/proyecto_bia/frontend/src/images/LogoBIA.png
[2025-08-08 00:21:26,825] WARNING django.request - Not Found: /proyecto_bia/frontend/src/images/LogoBIA.png
[2025-08-08 00:21:29,883] WARNING django.request - Not Found: /proyecto_bia/frontend/src/images/LogoBIA.png
[2025-08-08 00:21:32,215] WARNING django.request - Not Found: /proyecto_bia/frontend/src/images/LogoBIA.png
[2025-08-08 00:21:37,887] WARNING django.request - Not Found: /proyecto_bia/frontend/src/images/LogoBIA.png
[2025-08-08 00:21:42,246] WARNING django.request - Not Found: /datos/proyecto_bia/frontend/src/images/LogoBIA.png
[2025-08-08 00:21:44,884] WARNING django.request - Not Found: /carga-datos/proyecto_bia/frontend/src/images/LogoBIA.png
[2025-08-08 00:21:52,595] WARNING django.request - Not Found: /datos/proyecto_bia/frontend/src/images/LogoBIA.png
[2025-08-08 00:21:56,869] WARNING django.request - Not Found: /api/mostrar-datos-bia/
[2025-08-08 00:21:59,076] WARNING django.request - Not Found: /api/mostrar-datos-bia/
[2025-08-08 00:23:44,752] WARNING django.request - Not Found: /proyecto_bia/frontend/src/images/LogoBIA.png
[2025-08-08 00:23:47,353] WARNING django.request - Not Found: /proyecto_bia/frontend/src/images/LogoBIA.png
[2025-08-08 00:23:52,287] WARNING django.request - Not Found: /proyecto_bia/frontend/src/images/LogoBIA.png
[2025-08-08 00:23:54,011] WARNING django.request - Not Found: /proyecto_bia/frontend/src/images/LogoBIA.png
[2025-08-08 00:23:55,773] WARNING django.request - Not Found: /proyecto_bia/frontend/src/images/LogoBIA.png
[2025-08-08 00:23:57,054] WARNING django.request - Not Found: /proyecto_bia/frontend/src/images/LogoBIA.png
[2025-08-08 00:24:06,703] ERROR django.request - Internal Server Error: /api/certificado/generar/
Traceback (most recent call last):
  File "C:\Users\moreiracristian\Documents\moreira\GrupoBIA\venvbia\Lib\site-packages\django\db\backends\utils.py", line 105, in _execute
    return self.cursor.execute(sql, params)
           ^^^^^^^^^^^^^^^^^^^^^^^^^^^^^^^^
psycopg2.errors.UndefinedTable: relation "carga_datos_basededatosbia" does not exist
LINE 1: SELECT 1 AS "a" FROM "carga_datos_basededatosbia" WHERE "car...
                             ^


The above exception was the direct cause of the following exception:

Traceback (most recent call last):
  File "C:\Users\moreiracristian\Documents\moreira\GrupoBIA\venvbia\Lib\site-packages\django\core\handlers\exception.py", line 55, in inner
    response = get_response(request)
               ^^^^^^^^^^^^^^^^^^^^^
  File "C:\Users\moreiracristian\Documents\moreira\GrupoBIA\venvbia\Lib\site-packages\django\core\handlers\base.py", line 197, in _get_response
    response = wrapped_callback(request, *callback_args, **callback_kwargs)
               ^^^^^^^^^^^^^^^^^^^^^^^^^^^^^^^^^^^^^^^^^^^^^^^^^^^^^^^^^^^^
  File "C:\Users\moreiracristian\Documents\moreira\GrupoBIA\venvbia\Lib\site-packages\django\views\decorators\csrf.py", line 65, in _view_wrapper
    return view_func(request, *args, **kwargs)
           ^^^^^^^^^^^^^^^^^^^^^^^^^^^^^^^^^^^
  File "C:\Users\moreiracristian\Documents\moreira\GrupoBIA\proyecto_bia\proyecto_bia\certificado_ldd\views.py", line 50, in api_generar_certificado
    if not registros.exists():
           ^^^^^^^^^^^^^^^^^^
  File "C:\Users\moreiracristian\Documents\moreira\GrupoBIA\venvbia\Lib\site-packages\django\db\models\query.py", line 1288, in exists
    return self.query.has_results(using=self.db)
           ^^^^^^^^^^^^^^^^^^^^^^^^^^^^^^^^^^^^^
  File "C:\Users\moreiracristian\Documents\moreira\GrupoBIA\venvbia\Lib\site-packages\django\db\models\sql\query.py", line 660, in has_results
    return compiler.has_results()
           ^^^^^^^^^^^^^^^^^^^^^^
  File "C:\Users\moreiracristian\Documents\moreira\GrupoBIA\venvbia\Lib\site-packages\django\db\models\sql\compiler.py", line 1542, in has_results
    return bool(self.execute_sql(SINGLE))
                ^^^^^^^^^^^^^^^^^^^^^^^^
  File "C:\Users\moreiracristian\Documents\moreira\GrupoBIA\venvbia\Lib\site-packages\django\db\models\sql\compiler.py", line 1574, in execute_sql
    cursor.execute(sql, params)
  File "C:\Users\moreiracristian\Documents\moreira\GrupoBIA\venvbia\Lib\site-packages\django\db\backends\utils.py", line 122, in execute
    return super().execute(sql, params)
           ^^^^^^^^^^^^^^^^^^^^^^^^^^^^
  File "C:\Users\moreiracristian\Documents\moreira\GrupoBIA\venvbia\Lib\site-packages\django\db\backends\utils.py", line 79, in execute
    return self._execute_with_wrappers(
           ^^^^^^^^^^^^^^^^^^^^^^^^^^^^
  File "C:\Users\moreiracristian\Documents\moreira\GrupoBIA\venvbia\Lib\site-packages\django\db\backends\utils.py", line 92, in _execute_with_wrappers
    return executor(sql, params, many, context)
           ^^^^^^^^^^^^^^^^^^^^^^^^^^^^^^^^^^^^
  File "C:\Users\moreiracristian\Documents\moreira\GrupoBIA\venvbia\Lib\site-packages\django\db\backends\utils.py", line 100, in _execute
    with self.db.wrap_database_errors:
         ^^^^^^^^^^^^^^^^^^^^^^^^^^^^
  File "C:\Users\moreiracristian\Documents\moreira\GrupoBIA\venvbia\Lib\site-packages\django\db\utils.py", line 91, in __exit__
    raise dj_exc_value.with_traceback(traceback) from exc_value
  File "C:\Users\moreiracristian\Documents\moreira\GrupoBIA\venvbia\Lib\site-packages\django\db\backends\utils.py", line 105, in _execute
    return self.cursor.execute(sql, params)
           ^^^^^^^^^^^^^^^^^^^^^^^^^^^^^^^^
django.db.utils.ProgrammingError: relation "carga_datos_basededatosbia" does not exist
LINE 1: SELECT 1 AS "a" FROM "carga_datos_basededatosbia" WHERE "car...
                             ^

[2025-08-08 00:24:11,893] ERROR django.request - Internal Server Error: /api/certificado/generar/
Traceback (most recent call last):
  File "C:\Users\moreiracristian\Documents\moreira\GrupoBIA\venvbia\Lib\site-packages\django\db\backends\utils.py", line 105, in _execute
    return self.cursor.execute(sql, params)
           ^^^^^^^^^^^^^^^^^^^^^^^^^^^^^^^^
psycopg2.errors.UndefinedTable: relation "carga_datos_basededatosbia" does not exist
LINE 1: SELECT 1 AS "a" FROM "carga_datos_basededatosbia" WHERE "car...
                             ^


The above exception was the direct cause of the following exception:

Traceback (most recent call last):
  File "C:\Users\moreiracristian\Documents\moreira\GrupoBIA\venvbia\Lib\site-packages\django\core\handlers\exception.py", line 55, in inner
    response = get_response(request)
               ^^^^^^^^^^^^^^^^^^^^^
  File "C:\Users\moreiracristian\Documents\moreira\GrupoBIA\venvbia\Lib\site-packages\django\core\handlers\base.py", line 197, in _get_response
    response = wrapped_callback(request, *callback_args, **callback_kwargs)
               ^^^^^^^^^^^^^^^^^^^^^^^^^^^^^^^^^^^^^^^^^^^^^^^^^^^^^^^^^^^^
  File "C:\Users\moreiracristian\Documents\moreira\GrupoBIA\venvbia\Lib\site-packages\django\views\decorators\csrf.py", line 65, in _view_wrapper
    return view_func(request, *args, **kwargs)
           ^^^^^^^^^^^^^^^^^^^^^^^^^^^^^^^^^^^
  File "C:\Users\moreiracristian\Documents\moreira\GrupoBIA\proyecto_bia\proyecto_bia\certificado_ldd\views.py", line 50, in api_generar_certificado
    if not registros.exists():
           ^^^^^^^^^^^^^^^^^^
  File "C:\Users\moreiracristian\Documents\moreira\GrupoBIA\venvbia\Lib\site-packages\django\db\models\query.py", line 1288, in exists
    return self.query.has_results(using=self.db)
           ^^^^^^^^^^^^^^^^^^^^^^^^^^^^^^^^^^^^^
  File "C:\Users\moreiracristian\Documents\moreira\GrupoBIA\venvbia\Lib\site-packages\django\db\models\sql\query.py", line 660, in has_results
    return compiler.has_results()
           ^^^^^^^^^^^^^^^^^^^^^^
  File "C:\Users\moreiracristian\Documents\moreira\GrupoBIA\venvbia\Lib\site-packages\django\db\models\sql\compiler.py", line 1542, in has_results
    return bool(self.execute_sql(SINGLE))
                ^^^^^^^^^^^^^^^^^^^^^^^^
  File "C:\Users\moreiracristian\Documents\moreira\GrupoBIA\venvbia\Lib\site-packages\django\db\models\sql\compiler.py", line 1574, in execute_sql
    cursor.execute(sql, params)
  File "C:\Users\moreiracristian\Documents\moreira\GrupoBIA\venvbia\Lib\site-packages\django\db\backends\utils.py", line 122, in execute
    return super().execute(sql, params)
           ^^^^^^^^^^^^^^^^^^^^^^^^^^^^
  File "C:\Users\moreiracristian\Documents\moreira\GrupoBIA\venvbia\Lib\site-packages\django\db\backends\utils.py", line 79, in execute
    return self._execute_with_wrappers(
           ^^^^^^^^^^^^^^^^^^^^^^^^^^^^
  File "C:\Users\moreiracristian\Documents\moreira\GrupoBIA\venvbia\Lib\site-packages\django\db\backends\utils.py", line 92, in _execute_with_wrappers
    return executor(sql, params, many, context)
           ^^^^^^^^^^^^^^^^^^^^^^^^^^^^^^^^^^^^
  File "C:\Users\moreiracristian\Documents\moreira\GrupoBIA\venvbia\Lib\site-packages\django\db\backends\utils.py", line 100, in _execute
    with self.db.wrap_database_errors:
         ^^^^^^^^^^^^^^^^^^^^^^^^^^^^
  File "C:\Users\moreiracristian\Documents\moreira\GrupoBIA\venvbia\Lib\site-packages\django\db\utils.py", line 91, in __exit__
    raise dj_exc_value.with_traceback(traceback) from exc_value
  File "C:\Users\moreiracristian\Documents\moreira\GrupoBIA\venvbia\Lib\site-packages\django\db\backends\utils.py", line 105, in _execute
    return self.cursor.execute(sql, params)
           ^^^^^^^^^^^^^^^^^^^^^^^^^^^^^^^^
django.db.utils.ProgrammingError: relation "carga_datos_basededatosbia" does not exist
LINE 1: SELECT 1 AS "a" FROM "carga_datos_basededatosbia" WHERE "car...
                             ^

[2025-08-08 00:26:47,675] WARNING django.request - Not Found: /proyecto_bia/frontend/src/images/LogoBIA.png
[2025-08-08 00:26:48,600] WARNING django.request - Not Found: /proyecto_bia/frontend/src/images/LogoBIA.png
[2025-08-08 00:26:54,932] ERROR django.request - Internal Server Error: /api/certificado/generar/
Traceback (most recent call last):
  File "C:\Users\moreiracristian\Documents\moreira\GrupoBIA\venvbia\Lib\site-packages\django\db\backends\utils.py", line 105, in _execute
    return self.cursor.execute(sql, params)
           ^^^^^^^^^^^^^^^^^^^^^^^^^^^^^^^^
psycopg2.errors.UndefinedTable: relation "carga_datos_basededatosbia" does not exist
LINE 1: SELECT 1 AS "a" FROM "carga_datos_basededatosbia" WHERE "car...
                             ^


The above exception was the direct cause of the following exception:

Traceback (most recent call last):
  File "C:\Users\moreiracristian\Documents\moreira\GrupoBIA\venvbia\Lib\site-packages\django\core\handlers\exception.py", line 55, in inner
    response = get_response(request)
               ^^^^^^^^^^^^^^^^^^^^^
  File "C:\Users\moreiracristian\Documents\moreira\GrupoBIA\venvbia\Lib\site-packages\django\core\handlers\base.py", line 197, in _get_response
    response = wrapped_callback(request, *callback_args, **callback_kwargs)
               ^^^^^^^^^^^^^^^^^^^^^^^^^^^^^^^^^^^^^^^^^^^^^^^^^^^^^^^^^^^^
  File "C:\Users\moreiracristian\Documents\moreira\GrupoBIA\venvbia\Lib\site-packages\django\views\decorators\csrf.py", line 65, in _view_wrapper
    return view_func(request, *args, **kwargs)
           ^^^^^^^^^^^^^^^^^^^^^^^^^^^^^^^^^^^
  File "C:\Users\moreiracristian\Documents\moreira\GrupoBIA\proyecto_bia\proyecto_bia\certificado_ldd\views.py", line 50, in api_generar_certificado
    if not registros.exists():
           ^^^^^^^^^^^^^^^^^^
  File "C:\Users\moreiracristian\Documents\moreira\GrupoBIA\venvbia\Lib\site-packages\django\db\models\query.py", line 1288, in exists
    return self.query.has_results(using=self.db)
           ^^^^^^^^^^^^^^^^^^^^^^^^^^^^^^^^^^^^^
  File "C:\Users\moreiracristian\Documents\moreira\GrupoBIA\venvbia\Lib\site-packages\django\db\models\sql\query.py", line 660, in has_results
    return compiler.has_results()
           ^^^^^^^^^^^^^^^^^^^^^^
  File "C:\Users\moreiracristian\Documents\moreira\GrupoBIA\venvbia\Lib\site-packages\django\db\models\sql\compiler.py", line 1542, in has_results
    return bool(self.execute_sql(SINGLE))
                ^^^^^^^^^^^^^^^^^^^^^^^^
  File "C:\Users\moreiracristian\Documents\moreira\GrupoBIA\venvbia\Lib\site-packages\django\db\models\sql\compiler.py", line 1574, in execute_sql
    cursor.execute(sql, params)
  File "C:\Users\moreiracristian\Documents\moreira\GrupoBIA\venvbia\Lib\site-packages\django\db\backends\utils.py", line 122, in execute
    return super().execute(sql, params)
           ^^^^^^^^^^^^^^^^^^^^^^^^^^^^
  File "C:\Users\moreiracristian\Documents\moreira\GrupoBIA\venvbia\Lib\site-packages\django\db\backends\utils.py", line 79, in execute
    return self._execute_with_wrappers(
           ^^^^^^^^^^^^^^^^^^^^^^^^^^^^
  File "C:\Users\moreiracristian\Documents\moreira\GrupoBIA\venvbia\Lib\site-packages\django\db\backends\utils.py", line 92, in _execute_with_wrappers
    return executor(sql, params, many, context)
           ^^^^^^^^^^^^^^^^^^^^^^^^^^^^^^^^^^^^
  File "C:\Users\moreiracristian\Documents\moreira\GrupoBIA\venvbia\Lib\site-packages\django\db\backends\utils.py", line 100, in _execute
    with self.db.wrap_database_errors:
         ^^^^^^^^^^^^^^^^^^^^^^^^^^^^
  File "C:\Users\moreiracristian\Documents\moreira\GrupoBIA\venvbia\Lib\site-packages\django\db\utils.py", line 91, in __exit__
    raise dj_exc_value.with_traceback(traceback) from exc_value
  File "C:\Users\moreiracristian\Documents\moreira\GrupoBIA\venvbia\Lib\site-packages\django\db\backends\utils.py", line 105, in _execute
    return self.cursor.execute(sql, params)
           ^^^^^^^^^^^^^^^^^^^^^^^^^^^^^^^^
django.db.utils.ProgrammingError: relation "carga_datos_basededatosbia" does not exist
LINE 1: SELECT 1 AS "a" FROM "carga_datos_basededatosbia" WHERE "car...
                             ^

[2025-08-08 00:29:18,784] WARNING django.request - Not Found: /proyecto_bia/frontend/src/images/LogoBIA.png
[2025-08-08 00:29:20,583] WARNING django.request - Not Found: /proyecto_bia/frontend/src/images/LogoBIA.png
[2025-08-08 00:29:21,624] WARNING django.request - Not Found: /proyecto_bia/frontend/src/images/LogoBIA.png
[2025-08-08 00:29:22,667] WARNING django.request - Not Found: /proyecto_bia/frontend/src/images/LogoBIA.png
[2025-08-08 00:29:26,250] WARNING django.request - Not Found: /api/certificado/generar/
[2025-08-08 00:30:27,196] WARNING django.request - Not Found: /proyecto_bia/frontend/src/images/LogoBIA.png
[2025-08-08 00:30:29,695] WARNING django.request - Not Found: /proyecto_bia/frontend/src/images/LogoBIA.png
[2025-08-08 00:30:37,378] WARNING django.request - Not Found: /carga-datos/proyecto_bia/frontend/src/images/LogoBIA.png
[2025-08-08 00:30:42,571] WARNING django.request - Not Found: /proyecto_bia/frontend/src/images/LogoBIA.png
[2025-08-08 00:30:48,123] WARNING django.request - Not Found: /proyecto_bia/frontend/src/images/LogoBIA.png
[2025-08-08 00:30:50,437] WARNING django.request - Not Found: /carga-datos/proyecto_bia/frontend/src/images/LogoBIA.png
[2025-08-08 00:30:56,937] WARNING django.request - Not Found: /datos/proyecto_bia/frontend/src/images/LogoBIA.png
[2025-08-08 00:31:01,743] WARNING django.request - Not Found: /carga-datos/proyecto_bia/frontend/src/images/LogoBIA.png
[2025-08-08 00:31:04,062] WARNING django.request - Not Found: /datos/proyecto_bia/frontend/src/images/LogoBIA.png
[2025-08-08 00:31:04,753] WARNING django.request - Not Found: /proyecto_bia/frontend/src/images/LogoBIA.png
[2025-08-08 00:31:10,179] WARNING django.request - Not Found: /datos/proyecto_bia/frontend/src/images/LogoBIA.png
[2025-08-08 00:31:23,923] WARNING django.request - Not Found: /api/mostrar-datos-bia/
[2025-08-08 00:32:00,156] WARNING django.request - Not Found: /api/mostrar-datos-bia/
[2025-08-08 00:48:42,054] WARNING django.request - Not Found: /proyecto_bia/frontend/src/images/LogoBIA.png
[2025-08-08 00:48:44,277] WARNING django.request - Not Found: /proyecto_bia/frontend/src/images/LogoBIA.png
[2025-08-08 00:48:45,942] WARNING django.request - Not Found: /proyecto_bia/frontend/src/images/LogoBIA.png
[2025-08-08 00:48:47,544] WARNING django.request - Not Found: /datos/proyecto_bia/frontend/src/images/LogoBIA.png
[2025-08-08 00:49:01,538] WARNING django.request - Not Found: /api/mostrar-datos-bia/
[2025-08-08 00:49:03,967] WARNING django.request - Not Found: /api/mostrar-datos-bia/
[2025-08-08 00:49:17,344] WARNING django.request - Not Found: /carga-datos/proyecto_bia/frontend/src/images/LogoBIA.png
[2025-08-08 00:49:18,182] WARNING django.request - Not Found: /proyecto_bia/frontend/src/images/LogoBIA.png
[2025-08-08 00:49:19,626] WARNING django.request - Not Found: /proyecto_bia/frontend/src/images/LogoBIA.png
[2025-08-08 00:49:20,896] WARNING django.request - Not Found: /proyecto_bia/frontend/src/images/LogoBIA.png
[2025-08-08 00:49:21,995] WARNING django.request - Not Found: /carga-datos/proyecto_bia/frontend/src/images/LogoBIA.png
[2025-08-08 00:55:26,704] WARNING django.request - Not Found: /api/mostrar-datos-bia/
[2025-08-08 01:39:20,625] WARNING django.request - Unauthorized: /api/token/
[2025-08-08 01:39:44,940] WARNING django.request - Unauthorized: /api/token/
[2025-08-08 01:41:03,955] WARNING django.request - Not Found: /api/mostrar-datos-bia/
[2025-08-08 01:41:15,483] WARNING django.request - Not Found: /api/mostrar-datos-bia/
[2025-08-08 12:42:19,034] WARNING django.request - Not Found: /proyecto_bia/frontend/src/images/LogoBIA.png
[2025-08-08 12:42:19,035] WARNING django.request - Not Found: /proyecto_bia/frontend/public/images/ImagenBienvenida.jpg
[2025-08-08 12:55:39,323] WARNING django.request - Not Found: /proyecto_bia/frontend/public/images/ImagenBienvenida.jpg
[2025-08-08 12:55:39,324] WARNING django.request - Not Found: /proyecto_bia/frontend/src/images/LogoBIA.png
[2025-08-08 12:57:01,303] WARNING django.request - Not Found: /datos/proyecto_bia/frontend/src/images/LogoBIA.png
[2025-08-08 12:57:07,545] WARNING django.request - Not Found: /api/mostrar-datos-bia/
[2025-08-08 12:57:15,025] WARNING django.request - Not Found: /api/mostrar-datos-bia/
[2025-08-08 13:04:47,141] WARNING django.request - Not Found: /proyecto_bia/frontend/public/images/PuertoMadero.png
[2025-08-08 13:04:47,143] WARNING django.request - Not Found: /proyecto_bia/frontend/src/images/LogoBIA.png
[2025-08-08 13:05:07,471] WARNING django.request - Not Found: /proyecto_bia/frontend/src/images/LogoBIA.png
[2025-08-08 13:05:07,473] WARNING django.request - Not Found: /proyecto_bia/frontend/public/images/PuertoMadero.png
[2025-08-08 13:05:10,381] WARNING django.request - Not Found: /proyecto_bia/frontend/src/images/LogoBIA.png
[2025-08-08 13:05:10,383] WARNING django.request - Not Found: /proyecto_bia/frontend/public/images/PuertoMadero.png
[2025-08-08 13:05:11,113] WARNING django.request - Not Found: /proyecto_bia/frontend/src/images/LogoBIA.png
[2025-08-08 13:05:11,114] WARNING django.request - Not Found: /proyecto_bia/frontend/public/images/PuertoMadero.png
[2025-08-08 13:06:07,475] WARNING django.request - Not Found: /proyecto_bia/frontend/src/images/LogoBIA.png
[2025-08-08 13:06:07,477] WARNING django.request - Not Found: /proyecto_bia/frontend/public/images/PuertoMadero.png
[2025-08-08 13:06:08,328] WARNING django.request - Not Found: /proyecto_bia/frontend/src/images/LogoBIA.png
[2025-08-08 13:06:08,330] WARNING django.request - Not Found: /proyecto_bia/frontend/public/images/PuertoMadero.png
[2025-08-08 13:06:08,991] WARNING django.request - Not Found: /proyecto_bia/frontend/src/images/LogoBIA.png
[2025-08-08 13:06:08,992] WARNING django.request - Not Found: /proyecto_bia/frontend/public/images/PuertoMadero.png
[2025-08-08 13:06:51,342] WARNING django.request - Not Found: /proyecto_bia/frontend/public/images/LogoBIA.png
[2025-08-08 13:07:39,006] WARNING django.request - Not Found: /proyecto_bia/frontend/public/images/LogoBIA.png
[2025-08-08 13:07:39,008] WARNING django.request - Not Found: /proyecto_bia/frontend/public/images/PuertoMadero.png
[2025-08-08 13:07:46,167] WARNING django.request - Not Found: /proyecto_bia/frontend/public/images/PuertoMadero.png
[2025-08-08 13:07:46,169] WARNING django.request - Not Found: /proyecto_bia/frontend/public/images/LogoBIA.png
[2025-08-08 13:12:01,380] WARNING django.request - Not Found: /public/images/LogoBIA.png
[2025-08-08 13:12:01,390] WARNING django.request - Not Found: /public/images/LogoBIA.png
[2025-08-08 13:12:07,047] WARNING django.request - Not Found: /public/images/LogoBIA.png
[2025-08-08 13:12:07,049] WARNING django.request - Not Found: /proyecto_bia/frontend/public/images/PuertoMadero.png
[2025-08-08 13:12:07,848] WARNING django.request - Not Found: /public/images/LogoBIA.png
[2025-08-08 13:12:07,850] WARNING django.request - Not Found: /proyecto_bia/frontend/public/images/PuertoMadero.png
[2025-08-08 13:14:28,825] WARNING django.request - Not Found: /images/ImagenBienvenida.jpg
[2025-08-08 13:14:40,103] WARNING django.request - Not Found: /images/PuertoMadero.jpg
[2025-08-09 11:50:59,884] WARNING django.request - Not Found: /proyecto_bia/frontend/src/images/LogoBIA.png
[2025-08-09 11:51:10,138] WARNING django.request - Not Found: /datos/proyecto_bia/frontend/src/images/LogoBIA.png
[2025-08-09 11:51:15,971] WARNING django.request - Not Found: /carga-datos/proyecto_bia/frontend/src/images/LogoBIA.png
[2025-08-09 11:51:17,739] WARNING django.request - Not Found: /proyecto_bia/frontend/src/images/LogoBIA.png
[2025-08-09 11:51:20,144] WARNING django.request - Not Found: /proyecto_bia/frontend/src/images/LogoBIA.png
[2025-08-09 11:51:21,521] WARNING django.request - Not Found: /proyecto_bia/frontend/src/images/LogoBIA.png
[2025-08-09 11:51:24,377] WARNING django.request - Not Found: /proyecto_bia/frontend/src/images/LogoBIA.png
[2025-08-09 11:51:35,179] WARNING django.request - Not Found: /proyecto_bia/frontend/src/images/LogoBIA.png
[2025-08-09 12:02:39,159] WARNING django.request - Not Found: /proyecto_bia/frontend/src/images/LogoBIA.png
[2025-08-09 12:02:53,468] WARNING django.request - Not Found: /proyecto_bia/frontend/src/images/LogoBIA.png
[2025-08-09 12:02:55,629] WARNING django.request - Not Found: /proyecto_bia/frontend/src/images/LogoBIA.png
[2025-08-09 12:03:21,258] WARNING django.request - Not Found: /carga-datos/proyecto_bia/frontend/src/images/LogoBIA.png
[2025-08-09 12:03:24,624] WARNING django.request - Not Found: /proyecto_bia/frontend/src/images/LogoBIA.png
[2025-08-09 12:03:25,746] WARNING django.request - Not Found: /datos/proyecto_bia/frontend/src/images/LogoBIA.png
[2025-08-09 12:03:28,016] WARNING django.request - Not Found: /proyecto_bia/frontend/src/images/LogoBIA.png
[2025-08-09 12:03:32,694] WARNING django.request - Not Found: /proyecto_bia/frontend/src/images/LogoBIA.png
[2025-08-09 12:03:34,178] WARNING django.request - Not Found: /proyecto_bia/frontend/src/images/LogoBIA.png
[2025-08-09 12:03:43,454] WARNING django.request - Not Found: /proyecto_bia/frontend/src/images/LogoBIA.png
[2025-08-09 12:03:45,253] WARNING django.request - Not Found: /proyecto_bia/frontend/src/images/LogoBIA.png
[2025-08-09 12:03:55,579] WARNING django.request - Not Found: /carga-datos/proyecto_bia/frontend/src/images/LogoBIA.png
[2025-08-09 12:03:58,960] WARNING django.request - Not Found: /proyecto_bia/frontend/src/images/LogoBIA.png
[2025-08-09 12:04:02,649] WARNING django.request - Not Found: /carga-datos/proyecto_bia/frontend/src/images/LogoBIA.png
[2025-08-09 12:04:05,166] WARNING django.request - Not Found: /proyecto_bia/frontend/src/images/LogoBIA.png
[2025-08-09 12:04:07,257] WARNING django.request - Not Found: /datos/proyecto_bia/frontend/src/images/LogoBIA.png
[2025-08-09 12:04:09,402] WARNING django.request - Not Found: /proyecto_bia/frontend/src/images/LogoBIA.png
[2025-08-09 12:04:12,601] WARNING django.request - Not Found: /proyecto_bia/frontend/src/images/LogoBIA.png
[2025-08-09 12:10:32,744] WARNING django.request - Not Found: /proyecto_bia/frontend/src/images/LogoBIA.png
[2025-08-09 12:10:34,394] WARNING django.request - Not Found: /proyecto_bia/frontend/src/images/LogoBIA.png
[2025-08-09 12:13:01,275] WARNING django.request - Not Found: /proyecto_bia/frontend/src/images/LogoBIA.png
[2025-08-09 12:13:02,154] WARNING django.request - Not Found: /proyecto_bia/frontend/src/images/LogoBIA.png
[2025-08-09 12:13:05,175] WARNING django.request - Not Found: /proyecto_bia/frontend/src/images/LogoBIA.png
