[2025-08-13 23:53:57,818] WARNING django.request - Not Found: /api/entidades/
[2025-08-13 23:53:57,843] WARNING django.request - Not Found: /api/entidades/
[2025-08-19 00:02:08,920] WARNING django.request - Not Found: /api/certificado/generar/
[2025-08-19 00:04:35,744] ERROR django.request - Internal Server Error: /api/certificado/generar/
Traceback (most recent call last):
  File "C:\Users\moreiracristian\Documents\moreira\GrupoBIA\venvbia\Lib\site-packages\django\core\handlers\exception.py", line 55, in inner
    response = get_response(request)
               ^^^^^^^^^^^^^^^^^^^^^
  File "C:\Users\moreiracristian\Documents\moreira\GrupoBIA\venvbia\Lib\site-packages\django\core\handlers\base.py", line 197, in _get_response
    response = wrapped_callback(request, *callback_args, **callback_kwargs)
               ^^^^^^^^^^^^^^^^^^^^^^^^^^^^^^^^^^^^^^^^^^^^^^^^^^^^^^^^^^^^
  File "C:\Users\moreiracristian\Documents\moreira\GrupoBIA\venvbia\Lib\site-packages\django\views\decorators\csrf.py", line 65, in _view_wrapper
    return view_func(request, *args, **kwargs)
           ^^^^^^^^^^^^^^^^^^^^^^^^^^^^^^^^^^^
  File "C:\Users\moreiracristian\Documents\moreira\GrupoBIA\proyecto_bia\proyecto_bia\certificado_ldd\views.py", line 121, in api_generar_certificado
    with open(cert.pdf_file.path, 'rb') as f:
         ^^^^^^^^^^^^^^^^^^^^^^^^^^^^^^
FileNotFoundError: [Errno 2] No such file or directory: 'C:\\Users\\moreiracristian\\Documents\\moreira\\GrupoBIA\\proyecto_bia\\proyecto_bia\\media\\certificados_generados\\certificado_125478.pdf'
[2025-08-19 00:04:38,931] ERROR django.request - Internal Server Error: /api/certificado/generar/
Traceback (most recent call last):
  File "C:\Users\moreiracristian\Documents\moreira\GrupoBIA\venvbia\Lib\site-packages\django\core\handlers\exception.py", line 55, in inner
    response = get_response(request)
               ^^^^^^^^^^^^^^^^^^^^^
  File "C:\Users\moreiracristian\Documents\moreira\GrupoBIA\venvbia\Lib\site-packages\django\core\handlers\base.py", line 197, in _get_response
    response = wrapped_callback(request, *callback_args, **callback_kwargs)
               ^^^^^^^^^^^^^^^^^^^^^^^^^^^^^^^^^^^^^^^^^^^^^^^^^^^^^^^^^^^^
  File "C:\Users\moreiracristian\Documents\moreira\GrupoBIA\venvbia\Lib\site-packages\django\views\decorators\csrf.py", line 65, in _view_wrapper
    return view_func(request, *args, **kwargs)
           ^^^^^^^^^^^^^^^^^^^^^^^^^^^^^^^^^^^
  File "C:\Users\moreiracristian\Documents\moreira\GrupoBIA\proyecto_bia\proyecto_bia\certificado_ldd\views.py", line 121, in api_generar_certificado
    with open(cert.pdf_file.path, 'rb') as f:
         ^^^^^^^^^^^^^^^^^^^^^^^^^^^^^^
FileNotFoundError: [Errno 2] No such file or directory: 'C:\\Users\\moreiracristian\\Documents\\moreira\\GrupoBIA\\proyecto_bia\\proyecto_bia\\media\\certificados_generados\\certificado_125478.pdf'
[2025-08-19 00:06:18,463] WARNING django.request - Not Found: /api/entidades/
[2025-08-19 00:06:18,487] WARNING django.request - Not Found: /api/entidades/
[2025-08-19 00:07:46,168] WARNING django.request - Not Found: /api/mostrar-datos-bia/
[2025-08-20 01:14:05,900] WARNING django.request - Not Found: /api/entidades/
[2025-08-20 01:14:05,912] WARNING django.request - Not Found: /api/entidades/
[2025-08-20 01:14:13,228] WARNING django.request - Not Found: /api/entidades/
[2025-08-20 01:14:19,007] WARNING django.request - Not Found: /api/entidades/sugerencias/
[2025-08-20 01:14:30,864] WARNING django.request - Not Found: /api/entidades/
[2025-08-20 01:14:35,588] WARNING django.request - Not Found: /api/entidades/
[2025-08-20 01:15:19,345] WARNING django.request - Not Found: /api/mostrar-datos-bia/
[2025-08-20 01:15:21,806] WARNING django.request - Not Found: /api/mostrar-datos-bia/
[2025-08-20 01:15:24,951] WARNING django.request - Not Found: /api/entidades/
[2025-08-20 01:15:24,962] WARNING django.request - Not Found: /api/entidades/
[2025-08-20 01:15:56,390] WARNING django.request - Not Found: /api/entidades/
[2025-08-20 01:15:56,399] WARNING django.request - Not Found: /api/entidades/
[2025-08-20 01:16:27,815] WARNING django.request - Not Found: /api/mostrar-datos-bia/
[2025-08-22 19:42:35,393] WARNING django.request - Not Found: /api/entidades/
[2025-08-22 19:42:35,434] WARNING django.request - Not Found: /api/entidades/
[2025-08-22 19:43:15,683] WARNING django.request - Not Found: /api/entidades/
[2025-08-22 19:43:15,713] WARNING django.request - Not Found: /api/entidades/
[2025-08-22 19:43:34,032] WARNING django.request - Not Found: /api/entidades/
[2025-08-22 19:43:34,070] WARNING django.request - Not Found: /api/entidades/
[2025-08-22 19:44:20,136] WARNING django.request - Not Found: /api/mostrar-datos-bia/
[2025-08-22 19:45:31,570] WARNING django.request - Not Found: /api/entidades/
[2025-08-22 19:45:31,610] WARNING django.request - Not Found: /api/entidades/
[2025-08-22 19:57:15,579] WARNING django.request - Not Found: /api/entidades/
[2025-08-22 19:57:15,602] WARNING django.request - Not Found: /api/entidades/
[2025-08-23 01:25:17,897] WARNING django.request - Not Found: /api/entidades/
[2025-08-23 01:25:17,924] WARNING django.request - Not Found: /api/entidades/
[2025-08-23 01:29:04,811] WARNING django.request - Not Found: /api/certificado/generar/
[2025-08-23 02:48:22,996] WARNING django.request - Not Found: /api/entidades/
[2025-08-23 02:48:23,018] WARNING django.request - Not Found: /api/entidades/
[2025-08-23 02:48:33,564] WARNING django.request - Not Found: /api/entidades/sugerencias/
[2025-08-23 02:48:40,436] WARNING django.request - Not Found: /api/entidades/
[2025-08-23 02:48:48,920] WARNING django.request - Not Found: /api/entidades/
[2025-08-23 02:59:24,347] WARNING django.request - Not Found: /api/entidades/
[2025-08-23 02:59:24,381] WARNING django.request - Not Found: /api/entidades/
[2025-08-23 03:00:10,761] WARNING django.request - Not Found: /api/entidades/
[2025-08-23 03:00:10,806] WARNING django.request - Not Found: /api/entidades/
[2025-08-23 03:00:16,063] WARNING django.request - Not Found: /api/entidades/sugerencias/
[2025-08-23 03:00:23,360] WARNING django.request - Not Found: /api/entidades/
[2025-08-23 03:00:24,036] WARNING django.request - Not Found: /api/entidades/
[2025-08-23 03:00:24,219] WARNING django.request - Not Found: /api/entidades/
[2025-08-23 03:00:24,353] WARNING django.request - Not Found: /api/entidades/
[2025-08-23 03:00:24,467] WARNING django.request - Not Found: /api/entidades/
[2025-08-23 03:00:24,578] WARNING django.request - Not Found: /api/entidades/
[2025-08-23 03:00:24,745] WARNING django.request - Not Found: /api/entidades/
[2025-08-23 03:02:17,866] WARNING django.request - Not Found: /api/entidades/
[2025-08-23 03:19:21,465] WARNING django.request - Not Found: /api/entidades/
[2025-08-23 03:20:27,310] WARNING django.request - Not Found: /api/entidades/
[2025-08-23 03:20:27,334] WARNING django.request - Not Found: /api/entidades/
[2025-08-23 03:21:49,004] WARNING django.request - Not Found: /api/entidades/
[2025-08-23 03:23:03,290] WARNING django.request - Not Found: /api/entidades/
[2025-08-23 03:23:33,882] WARNING django.request - Not Found: /api/entidades/
[2025-08-23 03:23:34,335] WARNING django.request - Not Found: /favicon.ico
[2025-08-23 03:33:15,889] WARNING django.request - Unauthorized: /api/entidades/
[2025-08-23 03:33:15,900] WARNING django.request - Unauthorized: /api/entidades/
[2025-08-23 03:34:50,743] WARNING django.request - Not Found: /api/entidades/sugerencias/
[2025-08-23 03:35:19,767] WARNING django.request - Unauthorized: /api/entidades/
[2025-08-23 03:39:55,551] WARNING django.request - Unauthorized: /api/entidades/
[2025-08-23 03:40:05,478] WARNING django.request - Unauthorized: /api/entidades/sugerencias/
[2025-08-23 04:06:14,196] WARNING django.request - Unauthorized: /api/entidades/2/
[2025-08-23 04:07:16,424] WARNING django.request - Not Found: /api/entidades/sugerencias/
[2025-08-23 04:18:44,066] WARNING django.request - Not Found: /api/entidades/sugerencias/
[2025-08-23 04:25:29,197] WARNING django.request - Not Found: /api/entidades/sugerencias/
[2025-08-23 04:26:06,161] WARNING django.request - Not Found: /api/certificado/generar/
[2025-08-23 04:26:07,689] WARNING django.request - Not Found: /api/certificado/generar/
[2025-08-23 04:26:56,573] WARNING django.request - Not Found: /api/certificado/generar/
[2025-08-23 04:27:29,486] WARNING django.request - Not Found: /api/certificado/generar/
[2025-08-23 04:31:40,560] WARNING django.request - Not Found: /api/entidades/sugerencias/
[2025-08-23 04:32:03,089] WARNING django.request - Not Found: /api/certificado/generar/
[2025-08-23 04:34:21,923] WARNING django.request - Not Found: /api/entidades/sugerencias/
[2025-08-23 04:34:35,306] WARNING django.request - Not Found: /api/certificado/generar/
[2025-08-23 04:39:19,419] WARNING django.request - Not Found: /api/certificado/generar/
[2025-08-23 04:40:00,035] WARNING django.request - Unauthorized: /api/entidades/
[2025-08-23 04:40:00,046] WARNING django.request - Unauthorized: /api/entidades/
[2025-08-23 04:40:33,627] WARNING django.request - Not Found: /api/certificado/generar/
[2025-08-23 04:43:32,721] WARNING django.request - Not Found: /api/entidades/sugerencias/
[2025-08-23 04:44:11,080] WARNING django.request - Not Found: /api/entidades/sugerencias/
[2025-08-23 10:54:29,118] WARNING django.request - Not Found: /api/generar/
[2025-08-23 10:54:42,764] WARNING django.request - Unauthorized: /api/entidades/
[2025-08-23 10:54:42,787] WARNING django.request - Unauthorized: /api/entidades/
[2025-08-23 10:54:52,331] WARNING django.request - Not Found: /api/generar/
[2025-08-23 11:08:43,669] WARNING django.request - Not Found: /api/mostrar-datos-bia/
[2025-08-23 15:31:53,965] WARNING django.request - Unauthorized: /api/entidades/
[2025-08-23 15:31:53,973] WARNING django.request - Unauthorized: /api/entidades/
[2025-08-23 15:42:59,435] WARNING django.request - Not Found: /api/mostrar-datos-bia/
[2025-08-23 15:43:22,953] WARNING django.request - Not Found: /api/mostrar-datos-bia/
[2025-08-23 18:22:26,980] ERROR django.request - Internal Server Error: /api/generar/
Traceback (most recent call last):
  File "C:\Users\moreiracristian\Documents\moreira\GrupoBIA\venvbia\Lib\site-packages\django\db\backends\utils.py", line 105, in _execute
    return self.cursor.execute(sql, params)
           ^^^^^^^^^^^^^^^^^^^^^^^^^^^^^^^^
psycopg2.errors.UndefinedFunction: operator does not exist: character varying = integer
LINE 1: ...ROM "certificate" WHERE "certificate"."client_id" = 21 LIMIT...
                                                             ^
HINT:  No operator matches the given name and argument types. You might need to add explicit type casts.


The above exception was the direct cause of the following exception:

Traceback (most recent call last):
  File "C:\Users\moreiracristian\Documents\moreira\GrupoBIA\venvbia\Lib\site-packages\django\core\handlers\exception.py", line 55, in inner
    response = get_response(request)
               ^^^^^^^^^^^^^^^^^^^^^
  File "C:\Users\moreiracristian\Documents\moreira\GrupoBIA\venvbia\Lib\site-packages\django\core\handlers\base.py", line 197, in _get_response
    response = wrapped_callback(request, *callback_args, **callback_kwargs)
               ^^^^^^^^^^^^^^^^^^^^^^^^^^^^^^^^^^^^^^^^^^^^^^^^^^^^^^^^^^^^
  File "C:\Users\moreiracristian\Documents\moreira\GrupoBIA\venvbia\Lib\site-packages\django\views\decorators\csrf.py", line 65, in _view_wrapper
    return view_func(request, *args, **kwargs)
           ^^^^^^^^^^^^^^^^^^^^^^^^^^^^^^^^^^^
  File "C:\Users\moreiracristian\Documents\moreira\GrupoBIA\proyecto_bia\proyecto_bia\certificado_ldd\views.py", line 132, in api_generar_certificado
    certificate, created = Certificate.objects.get_or_create(client=registro)
                           ^^^^^^^^^^^^^^^^^^^^^^^^^^^^^^^^^^^^^^^^^^^^^^^^^^
  File "C:\Users\moreiracristian\Documents\moreira\GrupoBIA\venvbia\Lib\site-packages\django\db\models\manager.py", line 87, in manager_method
    return getattr(self.get_queryset(), name)(*args, **kwargs)
           ^^^^^^^^^^^^^^^^^^^^^^^^^^^^^^^^^^^^^^^^^^^^^^^^^^^
  File "C:\Users\moreiracristian\Documents\moreira\GrupoBIA\venvbia\Lib\site-packages\django\db\models\query.py", line 948, in get_or_create
    return self.get(**kwargs), False
           ^^^^^^^^^^^^^^^^^^
  File "C:\Users\moreiracristian\Documents\moreira\GrupoBIA\venvbia\Lib\site-packages\django\db\models\query.py", line 645, in get
    num = len(clone)
          ^^^^^^^^^^
  File "C:\Users\moreiracristian\Documents\moreira\GrupoBIA\venvbia\Lib\site-packages\django\db\models\query.py", line 382, in __len__
    self._fetch_all()
  File "C:\Users\moreiracristian\Documents\moreira\GrupoBIA\venvbia\Lib\site-packages\django\db\models\query.py", line 1928, in _fetch_all
    self._result_cache = list(self._iterable_class(self))
                         ^^^^^^^^^^^^^^^^^^^^^^^^^^^^^^^^
  File "C:\Users\moreiracristian\Documents\moreira\GrupoBIA\venvbia\Lib\site-packages\django\db\models\query.py", line 91, in __iter__
    results = compiler.execute_sql(
              ^^^^^^^^^^^^^^^^^^^^^
  File "C:\Users\moreiracristian\Documents\moreira\GrupoBIA\venvbia\Lib\site-packages\django\db\models\sql\compiler.py", line 1574, in execute_sql
    cursor.execute(sql, params)
  File "C:\Users\moreiracristian\Documents\moreira\GrupoBIA\venvbia\Lib\site-packages\django\db\backends\utils.py", line 122, in execute
    return super().execute(sql, params)
           ^^^^^^^^^^^^^^^^^^^^^^^^^^^^
  File "C:\Users\moreiracristian\Documents\moreira\GrupoBIA\venvbia\Lib\site-packages\django\db\backends\utils.py", line 79, in execute
    return self._execute_with_wrappers(
           ^^^^^^^^^^^^^^^^^^^^^^^^^^^^
  File "C:\Users\moreiracristian\Documents\moreira\GrupoBIA\venvbia\Lib\site-packages\django\db\backends\utils.py", line 92, in _execute_with_wrappers
    return executor(sql, params, many, context)
           ^^^^^^^^^^^^^^^^^^^^^^^^^^^^^^^^^^^^
  File "C:\Users\moreiracristian\Documents\moreira\GrupoBIA\venvbia\Lib\site-packages\django\db\backends\utils.py", line 100, in _execute
    with self.db.wrap_database_errors:
         ^^^^^^^^^^^^^^^^^^^^^^^^^^^^
  File "C:\Users\moreiracristian\Documents\moreira\GrupoBIA\venvbia\Lib\site-packages\django\db\utils.py", line 91, in __exit__
    raise dj_exc_value.with_traceback(traceback) from exc_value
  File "C:\Users\moreiracristian\Documents\moreira\GrupoBIA\venvbia\Lib\site-packages\django\db\backends\utils.py", line 105, in _execute
    return self.cursor.execute(sql, params)
           ^^^^^^^^^^^^^^^^^^^^^^^^^^^^^^^^
django.db.utils.ProgrammingError: operator does not exist: character varying = integer
LINE 1: ...ROM "certificate" WHERE "certificate"."client_id" = 21 LIMIT...
                                                             ^
HINT:  No operator matches the given name and argument types. You might need to add explicit type casts.

[2025-08-24 00:21:14,786] WARNING django.request - Unauthorized: /api/mostrar-datos-bia/
[2025-08-24 00:28:47,145] WARNING django.request - Not Found: /api/generar/
[2025-08-24 00:28:57,902] WARNING django.request - Not Found: /api/generar/
[2025-08-24 00:29:15,634] ERROR django.request - Internal Server Error: /api/generar/
Traceback (most recent call last):
  File "C:\Users\moreiracristian\Documents\moreira\GrupoBIA\venvbia\Lib\site-packages\django\db\backends\utils.py", line 105, in _execute
    return self.cursor.execute(sql, params)
           ^^^^^^^^^^^^^^^^^^^^^^^^^^^^^^^^
psycopg2.errors.UndefinedFunction: operator does not exist: character varying = integer
LINE 1: ...ROM "certificate" WHERE "certificate"."client_id" = 15 LIMIT...
                                                             ^
HINT:  No operator matches the given name and argument types. You might need to add explicit type casts.


The above exception was the direct cause of the following exception:

Traceback (most recent call last):
  File "C:\Users\moreiracristian\Documents\moreira\GrupoBIA\venvbia\Lib\site-packages\django\core\handlers\exception.py", line 55, in inner
    response = get_response(request)
               ^^^^^^^^^^^^^^^^^^^^^
  File "C:\Users\moreiracristian\Documents\moreira\GrupoBIA\venvbia\Lib\site-packages\django\core\handlers\base.py", line 197, in _get_response
    response = wrapped_callback(request, *callback_args, **callback_kwargs)
               ^^^^^^^^^^^^^^^^^^^^^^^^^^^^^^^^^^^^^^^^^^^^^^^^^^^^^^^^^^^^
  File "C:\Users\moreiracristian\Documents\moreira\GrupoBIA\venvbia\Lib\site-packages\django\views\decorators\csrf.py", line 65, in _view_wrapper
    return view_func(request, *args, **kwargs)
           ^^^^^^^^^^^^^^^^^^^^^^^^^^^^^^^^^^^
  File "C:\Users\moreiracristian\Documents\moreira\GrupoBIA\proyecto_bia\proyecto_bia\certificado_ldd\views.py", line 132, in api_generar_certificado
    certificate, created = Certificate.objects.get_or_create(client=registro)
                           ^^^^^^^^^^^^^^^^^^^^^^^^^^^^^^^^^^^^^^^^^^^^^^^^^^
  File "C:\Users\moreiracristian\Documents\moreira\GrupoBIA\venvbia\Lib\site-packages\django\db\models\manager.py", line 87, in manager_method
    return getattr(self.get_queryset(), name)(*args, **kwargs)
           ^^^^^^^^^^^^^^^^^^^^^^^^^^^^^^^^^^^^^^^^^^^^^^^^^^^
  File "C:\Users\moreiracristian\Documents\moreira\GrupoBIA\venvbia\Lib\site-packages\django\db\models\query.py", line 948, in get_or_create
    return self.get(**kwargs), False
           ^^^^^^^^^^^^^^^^^^
  File "C:\Users\moreiracristian\Documents\moreira\GrupoBIA\venvbia\Lib\site-packages\django\db\models\query.py", line 645, in get
    num = len(clone)
          ^^^^^^^^^^
  File "C:\Users\moreiracristian\Documents\moreira\GrupoBIA\venvbia\Lib\site-packages\django\db\models\query.py", line 382, in __len__
    self._fetch_all()
  File "C:\Users\moreiracristian\Documents\moreira\GrupoBIA\venvbia\Lib\site-packages\django\db\models\query.py", line 1928, in _fetch_all
    self._result_cache = list(self._iterable_class(self))
                         ^^^^^^^^^^^^^^^^^^^^^^^^^^^^^^^^
  File "C:\Users\moreiracristian\Documents\moreira\GrupoBIA\venvbia\Lib\site-packages\django\db\models\query.py", line 91, in __iter__
    results = compiler.execute_sql(
              ^^^^^^^^^^^^^^^^^^^^^
  File "C:\Users\moreiracristian\Documents\moreira\GrupoBIA\venvbia\Lib\site-packages\django\db\models\sql\compiler.py", line 1574, in execute_sql
    cursor.execute(sql, params)
  File "C:\Users\moreiracristian\Documents\moreira\GrupoBIA\venvbia\Lib\site-packages\django\db\backends\utils.py", line 122, in execute
    return super().execute(sql, params)
           ^^^^^^^^^^^^^^^^^^^^^^^^^^^^
  File "C:\Users\moreiracristian\Documents\moreira\GrupoBIA\venvbia\Lib\site-packages\django\db\backends\utils.py", line 79, in execute
    return self._execute_with_wrappers(
           ^^^^^^^^^^^^^^^^^^^^^^^^^^^^
  File "C:\Users\moreiracristian\Documents\moreira\GrupoBIA\venvbia\Lib\site-packages\django\db\backends\utils.py", line 92, in _execute_with_wrappers
    return executor(sql, params, many, context)
           ^^^^^^^^^^^^^^^^^^^^^^^^^^^^^^^^^^^^
  File "C:\Users\moreiracristian\Documents\moreira\GrupoBIA\venvbia\Lib\site-packages\django\db\backends\utils.py", line 100, in _execute
    with self.db.wrap_database_errors:
         ^^^^^^^^^^^^^^^^^^^^^^^^^^^^
  File "C:\Users\moreiracristian\Documents\moreira\GrupoBIA\venvbia\Lib\site-packages\django\db\utils.py", line 91, in __exit__
    raise dj_exc_value.with_traceback(traceback) from exc_value
  File "C:\Users\moreiracristian\Documents\moreira\GrupoBIA\venvbia\Lib\site-packages\django\db\backends\utils.py", line 105, in _execute
    return self.cursor.execute(sql, params)
           ^^^^^^^^^^^^^^^^^^^^^^^^^^^^^^^^
django.db.utils.ProgrammingError: operator does not exist: character varying = integer
LINE 1: ...ROM "certificate" WHERE "certificate"."client_id" = 15 LIMIT...
                                                             ^
HINT:  No operator matches the given name and argument types. You might need to add explicit type casts.

[2025-08-24 13:21:52,944] WARNING django.request - Unauthorized: /api/entidades/
[2025-08-24 13:21:52,967] WARNING django.request - Unauthorized: /api/entidades/
[2025-08-24 13:22:32,910] ERROR django.request - Internal Server Error: /api/generar/
Traceback (most recent call last):
  File "C:\Users\moreiracristian\Documents\moreira\GrupoBIA\venvbia\Lib\site-packages\django\core\handlers\exception.py", line 55, in inner
    response = get_response(request)
               ^^^^^^^^^^^^^^^^^^^^^
  File "C:\Users\moreiracristian\Documents\moreira\GrupoBIA\venvbia\Lib\site-packages\django\core\handlers\base.py", line 197, in _get_response
    response = wrapped_callback(request, *callback_args, **callback_kwargs)
               ^^^^^^^^^^^^^^^^^^^^^^^^^^^^^^^^^^^^^^^^^^^^^^^^^^^^^^^^^^^^
  File "C:\Users\moreiracristian\Documents\moreira\GrupoBIA\venvbia\Lib\site-packages\django\views\decorators\csrf.py", line 65, in _view_wrapper
    return view_func(request, *args, **kwargs)
           ^^^^^^^^^^^^^^^^^^^^^^^^^^^^^^^^^^^
  File "C:\Users\moreiracristian\Documents\moreira\GrupoBIA\proyecto_bia\proyecto_bia\certificado_ldd\views.py", line 179, in api_generar_certificado
    with open(cert.pdf_file.path, "rb") as f:
         ^^^^^^^^^^^^^^^^^^^^^^^^^^^^^^
FileNotFoundError: [Errno 2] No such file or directory: 'C:\\Users\\moreiracristian\\Documents\\moreira\\GrupoBIA\\proyecto_bia\\proyecto_bia\\media\\certificados_generados\\certificado_125478.pdf'
[2025-08-24 14:17:44,459] WARNING django.request - Not Found: /api/generar/
[2025-08-24 14:38:13,329] WARNING django.request - Not Found: /api/generar-certificado/
[2025-08-24 14:38:25,395] WARNING django.request - Not Found: /api/generar-certificado/
[2025-08-24 14:38:41,532] WARNING django.request - Not Found: /api/generar-certificado/
[2025-08-24 16:05:31,168] ERROR django.request - Internal Server Error: /api/generar-certificado/
Traceback (most recent call last):
  File "C:\Users\moreiracristian\Documents\moreira\GrupoBIA\venvbia\Lib\site-packages\django\core\handlers\exception.py", line 55, in inner
    response = get_response(request)
               ^^^^^^^^^^^^^^^^^^^^^
  File "C:\Users\moreiracristian\Documents\moreira\GrupoBIA\venvbia\Lib\site-packages\django\core\handlers\base.py", line 197, in _get_response
    response = wrapped_callback(request, *callback_args, **callback_kwargs)
               ^^^^^^^^^^^^^^^^^^^^^^^^^^^^^^^^^^^^^^^^^^^^^^^^^^^^^^^^^^^^
  File "C:\Users\moreiracristian\Documents\moreira\GrupoBIA\venvbia\Lib\site-packages\django\views\decorators\csrf.py", line 65, in _view_wrapper
    return view_func(request, *args, **kwargs)
           ^^^^^^^^^^^^^^^^^^^^^^^^^^^^^^^^^^^
  File "C:\Users\moreiracristian\Documents\moreira\GrupoBIA\proyecto_bia\proyecto_bia\certificado_ldd\views.py", line 256, in api_generar_certificado
    resp = HttpResponse(pdf, content_type="application/pdf")
           ^^^^^^^^^^^^
NameError: name 'HttpResponse' is not defined. Did you mean: 'JsonResponse'?
[2025-08-24 16:07:37,655] WARNING django.request - Not Found: /api/generar-certificado/
[2025-08-24 16:08:07,722] ERROR django.request - Internal Server Error: /api/generar-certificado/
Traceback (most recent call last):
  File "C:\Users\moreiracristian\Documents\moreira\GrupoBIA\venvbia\Lib\site-packages\django\core\handlers\exception.py", line 55, in inner
    response = get_response(request)
               ^^^^^^^^^^^^^^^^^^^^^
  File "C:\Users\moreiracristian\Documents\moreira\GrupoBIA\venvbia\Lib\site-packages\django\core\handlers\base.py", line 197, in _get_response
    response = wrapped_callback(request, *callback_args, **callback_kwargs)
               ^^^^^^^^^^^^^^^^^^^^^^^^^^^^^^^^^^^^^^^^^^^^^^^^^^^^^^^^^^^^
  File "C:\Users\moreiracristian\Documents\moreira\GrupoBIA\venvbia\Lib\site-packages\django\views\decorators\csrf.py", line 65, in _view_wrapper
    return view_func(request, *args, **kwargs)
           ^^^^^^^^^^^^^^^^^^^^^^^^^^^^^^^^^^^
  File "C:\Users\moreiracristian\Documents\moreira\GrupoBIA\proyecto_bia\proyecto_bia\certificado_ldd\views.py", line 256, in api_generar_certificado
    resp = HttpResponse(pdf, content_type="application/pdf")
           ^^^^^^^^^^^^
NameError: name 'HttpResponse' is not defined. Did you mean: 'JsonResponse'?
[2025-08-24 16:11:25,305] ERROR django.request - Internal Server Error: /api/generar-certificado/
Traceback (most recent call last):
  File "C:\Users\moreiracristian\Documents\moreira\GrupoBIA\venvbia\Lib\site-packages\django\core\handlers\exception.py", line 55, in inner
    response = get_response(request)
               ^^^^^^^^^^^^^^^^^^^^^
  File "C:\Users\moreiracristian\Documents\moreira\GrupoBIA\venvbia\Lib\site-packages\django\core\handlers\base.py", line 197, in _get_response
    response = wrapped_callback(request, *callback_args, **callback_kwargs)
               ^^^^^^^^^^^^^^^^^^^^^^^^^^^^^^^^^^^^^^^^^^^^^^^^^^^^^^^^^^^^
  File "C:\Users\moreiracristian\Documents\moreira\GrupoBIA\venvbia\Lib\site-packages\django\views\decorators\csrf.py", line 65, in _view_wrapper
    return view_func(request, *args, **kwargs)
           ^^^^^^^^^^^^^^^^^^^^^^^^^^^^^^^^^^^
  File "C:\Users\moreiracristian\Documents\moreira\GrupoBIA\proyecto_bia\proyecto_bia\certificado_ldd\views.py", line 256, in api_generar_certificado
    resp = HttpResponse(pdf, content_type="application/pdf")
           ^^^^^^^^^^^^
NameError: name 'HttpResponse' is not defined. Did you mean: 'JsonResponse'?
[2025-08-24 17:17:43,279] WARNING django.request - Not Found: /main.0abbbcf65d4c8087502c.hot-update.json
[2025-08-24 17:18:01,897] WARNING django.request - Not Found: /api/generar-certificado/
[2025-08-24 17:32:23,495] ERROR django.request - Internal Server Error: /api/generar-certificado/
[2025-08-24 17:41:31,661] WARNING django.request - Not Found: /api/generar-certificado/
